Workbook

Sheet Importar
A1: =External!C5 -> Control.Aportes[1]:x | B1: =External!D5 -> Control.Aportes[1]:y | C1: =External!E5 -> Control.Aportes[2]:x | D1: =External!F5 -> Control.Aportes[2]:y | E1: =External!G5 -> Control.Aportes[3]:x | F1: =External!H5 -> Control.Aportes[3]:y | G1: =External!I5 -> Control.Aportes[4]:x | H1: =External!J5 -> Control.Aportes[4]:y | ... ET1: =External!EV5 -> Control.Viento[25]:y
A2: 1 | B2: =External!D6 -> 4592.7556 | C2: =External!E6 -> 1 | D2: =External!F6 -> 4592.7556 | E2: =External!G6 -> 1 | F2: =External!H6 -> 4592.7556 | G2: =External!I6 -> 1 | H2: =External!J6 -> 4592.7556 | I2: =External!K6 -> 1 | ... ET2: =External!EV6 -> 11.1005
A3: 2 | B3: =External!D7 -> 3763.3693 | C3: =External!E7 -> 2 | D3: =External!F7 -> 3763.3693 | E3: =External!G7 -> 2 | F3: =External!H7 -> 3763.3693 | G3: =External!I7 -> 2 | H3: =External!J7 -> 3763.3693 | I3: =External!K7 -> 2 | ... ET3: =External!EV7 -> 11.032
A4: 3 | B4: =External!D8 -> 8711.2803 | C4: =External!E8 -> 3 | D4: =External!F8 -> 8711.2803 | E4: =External!G8 -> 3 | F4: =External!H8 -> 8711.2803 | G4: =External!I8 -> 3 | H4: =External!J8 -> 8711.2803 | I4: =External!K8 -> 3 | ... ET4: =External!EV8 -> 11.159
A5: 4 | B5: =External!D9 -> 8381.5881 | C5: =External!E9 -> 4 | D5: =External!F9 -> 8381.5881 | E5: =External!G9 -> 4 | F5: =External!H9 -> 8381.5881 | G5: =External!I9 -> 4 | H5: =External!J9 -> 8381.5881 | I5: =External!K9 -> 4 | ... ET5: =External!EV9 -> 10.8205
A6: 5 | B6: =External!D10 -> 9784.91 | C6: =External!E10 -> 5 | D6: =External!F10 -> 9784.91 | E6: =External!G10 -> 5 | F6: =External!H10 -> 9784.91 | G6: =External!I10 -> 5 | H6: =External!J10 -> 9784.91 | I6: =External!K10 -> 5 | ... ET6: =External!EV10 -> 11.2455
A7: 6 | B7: =External!D11 -> 9784.91 | C7: =External!E11 -> 6 | D7: =External!F11 -> 9784.91 | E7: =External!G11 -> 6 | F7: =External!H11 -> 9784.91 | G7: =External!I11 -> 6 | H7: =External!J11 -> 9784.91 | I7: =External!K11 -> 6 | ... ET7: =External!EV11 -> 12.095
A8: 7 | B8: =External!D12 -> 9784.91 | C8: =External!E12 -> 7 | D8: =External!F12 -> 9784.91 | E8: =External!G12 -> 7 | F8: =External!H12 -> 9784.91 | G8: =External!I12 -> 7 | H8: =External!J12 -> 9784.91 | I8: =External!K12 -> 7 | ... ET8: =External!EV12 -> 11.693
A9: 8 | B9: =External!D13 -> 9784.91 | C9: =External!E13 -> 8 | D9: =External!F13 -> 9784.91 | E9: =External!G13 -> 8 | F9: =External!H13 -> 9784.91 | G9: =External!I13 -> 8 | H9: =External!J13 -> 9784.91 | I9: =External!K13 -> 8 | ... ET9: =External!EV13 -> 10.5865
A10: 9 | B10: =External!D14 -> 8731.5199 | C10: =External!E14 -> 9 | D10: =External!F14 -> 8731.5199 | E10: =External!G14 -> 9 | F10: =External!H14 -> 8731.5199 | G10: =External!I14 -> 9 | H10: =External!J14 -> 8731.5199 | I10: =External!K14 -> 9 | ... ET10: =External!EV14 -> 8.532
A11: 10 | B11: =External!D15 -> 9460.9386 | C11: =External!E15 -> 10 | D11: =External!F15 -> 9460.9386 | E11: =External!G15 -> 10 | F11: =External!H15 -> 9460.9386 | G11: =External!I15 -> 10 | H11: =External!J15 -> 9460.9386 | I11: =External!K15 -> 10 | ... ET11: =External!EV15 -> 8.188
A12: 11 | B12: =External!D16 -> 9239.0186 | C12: =External!E16 -> 11 | D12: =External!F16 -> 9239.0186 | E12: =External!G16 -> 11 | F12: =External!H16 -> 9239.0186 | G12: =External!I16 -> 11 | H12: =External!J16 -> 9239.0186 | I12: =External!K16 -> 11 | ... ET12: =External!EV16 -> 9.2525
A13: 12 | B13: =External!D17 -> 5616.5134 | C13: =External!E17 -> 12 | D13: =External!F17 -> 5616.5134 | E13: =External!G17 -> 12 | F13: =External!H17 -> 5616.5134 | G13: =External!I17 -> 12 | H13: =External!J17 -> 5616.5134 | I13: =External!K17 -> 12 | ... ET13: =External!EV17 -> 10.7655
... A361: 360 | B361: =External!D365 -> 4914.45 | C361: =External!E365 -> 360 | D361: =External!F365 -> 6216.7974 | E361: =External!G365 -> 360 | F361: =External!H365 -> 6258.731 | G361: =External!I365 -> 360 | H361: =External!J365 -> 6577.9938 | I361: =External!K365 -> 360 | ... ET361: =External!EV365 -> 10.048

Sheet Sheet4
A1: Control.Aportes[1]:x | B1: Control.Aportes[1]:y | C1: Control.Aportes[2]:x | D1: Control.Aportes[2]:y
A2: 1 | B2: 2017.46 | C2: 1 | D2: 2135.05
A3: 2 | B3: 2109.01 | C3: 2 | D3: 2296.52
A4: 3 | B4: 2518.63 | C4: 3 | D4: 3205.21
A5: 4 | B5: 3078.96 | C5: 4 | D5: 4330.9
A6: 5 | B6: 4725.5 | C6: 5 | D6: 5864.6
A7: 6 | B7: 6170.32 | C7: 6 | D7: 5927.68
A8: 7 | B8: 4752.41 | C8: 7 | D8: 5144.79
A9: 8 | B9: 4670.36 | C9: 8 | D9: 5012.88
A10: 9 | B10: 4878.42 | C10: 9 | D10: 3329.44
A11: 10 | B11: 4235.02 | C11: 10 | D11: 4899.03
A12: 11 | B12: 4570.9 | C12: 11 | D12: 4111.15
A13: 12 | B13: 3276.3 | C13: 12 | D13: 2879.21
... A122: 121 | B122: 2875.12 | C122: 121 | D122: 2875.12

Sheet Datos
C1: Aportes | AB1: Radiación | BA1: Viento
C2: 1 | D2: =C2+1 -> 2 | E2: =D2+1 -> 3 | F2: =E2+1 -> 4 | G2: =F2+1 -> 5 | H2: =G2+1 -> 6 | I2: =H2+1 -> 7 | J2: =I2+1 -> 8 | K2: =J2+1 -> 9 | ... BY2: =BX2+1 -> 75
B3: SERIES | C3: 1 | D3: =IF(C3=25,1,C3+1) -> 2 | E3: =IF(D3=25,1,D3+1) -> 3 | F3: =IF(E3=25,1,E3+1) -> 4 | G3: =IF(F3=25,1,F3+1) -> 5 | H3: =IF(G3=25,1,G3+1) -> 6 | I3: =IF(H3=25,1,H3+1) -> 7 | J3: =IF(I3=25,1,I3+1) -> 8 | K3: =IF(J3=25,1,J3+1) -> 9 | ... AZ3: =IF(AY3=25,1,AY3+1) -> 25 | BA3: =IF(AZ3=25,1,AU3+1) -> 1 | BB3: =IF(BA3=25,1,BA3+1) -> 2 | BC3: =IF(BB3=25,1,BB3+1) -> 3 | BD3: =IF(BC3=25,1,BC3+1) -> 4 | BE3: =IF(BD3=25,1,BD3+1) -> 5 | BF3: =IF(BE3=25,1,BE3+1) -> 6 | BG3: =IF(BF3=25,1,BF3+1) -> 7 | BH3: =IF(BG3=25,1,BG3+1) -> 8 | BI3: =IF(BH3=25,1,BH3+1) -> 9 | ... BY3: =IF(BX3=25,1,BX3+1) -> 25
A4: 1 | C4: =CONCATENATE("Control.Aportes[",C3,"]:y") -> Control.Aportes[1]:y | D4: =CONCATENATE("Control.Aportes[",D3,"]:y") -> Control.Aportes[2]:y | E4: =CONCATENATE("Control.Aportes[",E3,"]:y") -> Control.Aportes[3]:y | F4: =CONCATENATE("Control.Aportes[",F3,"]:y") -> Control.Aportes[4]:y | G4: =CONCATENATE("Control.Aportes[",G3,"]:y") -> Control.Aportes[5]:y | H4: =CONCATENATE("Control.Aportes[",H3,"]:y") -> Control.Aportes[6]:y | I4: =CONCATENATE("Control.Aportes[",I3,"]:y") -> Control.Aportes[7]:y | J4: =CONCATENATE("Control.Aportes[",J3,"]:y") -> Control.Aportes[8]:y | ... AA4: =CONCATENATE("Control.Aportes[",AA3,"]:y") -> Control.Aportes[25]:y | AB4: =CONCATENATE("Control.Radiacion[",AB3,"]:y") -> Control.Radiacion[1]:y | AC4: =CONCATENATE("Control.Radiacion[",AC3,"]:y") -> Control.Radiacion[2]:y | AD4: =CONCATENATE("Control.Radiacion[",AD3,"]:y") -> Control.Radiacion[3]:y | AE4: =CONCATENATE("Control.Radiacion[",AE3,"]:y") -> Control.Radiacion[4]:y | AF4: =CONCATENATE("Control.Radiacion[",AF3,"]:y") -> Control.Radiacion[5]:y | AG4: =CONCATENATE("Control.Radiacion[",AG3,"]:y") -> Control.Radiacion[6]:y | AH4: =CONCATENATE("Control.Radiacion[",AH3,"]:y") -> Control.Radiacion[7]:y | AI4: =CONCATENATE("Control.Radiacion[",AI3,"]:y") -> Control.Radiacion[8]:y | ... AZ4: =CONCATENATE("Control.Radiacion[",AZ3,"]:y") -> Control.Radiacion[25]:y | BA4: =CONCATENATE("Control.Viento[",BA3,"]:y") -> Control.Viento[1]:y | BB4: =CONCATENATE("Control.Viento[",BB3,"]:y") -> Control.Viento[2]:y | BC4: =CONCATENATE("Control.Viento[",BC3,"]:y") -> Control.Viento[3]:y | BD4: =CONCATENATE("Control.Viento[",BD3,"]:y") -> Control.Viento[4]:y | BE4: =CONCATENATE("Control.Viento[",BE3,"]:y") -> Control.Viento[5]:y | BF4: =CONCATENATE("Control.Viento[",BF3,"]:y") -> Control.Viento[6]:y | BG4: =CONCATENATE("Control.Viento[",BG3,"]:y") -> Control.Viento[7]:y | BH4: =CONCATENATE("Control.Viento[",BH3,"]:y") -> Control.Viento[8]:y | ... BY4: =CONCATENATE("Control.Viento[",BY3,"]:y") -> Control.Viento[25]:y
A5: =A4+1 -> 2 | B5: 44197 | C5: 4592.7556 | D5: 4592.7556 | E5: 4592.7556 | F5: 4592.7556 | G5: 4592.7556 | H5: 4592.7556 | I5: 4592.7556 | J5: 4592.7556 | K5: 4592.7556 | L5: 4592.7556 | M5: 4592.7556 | N5: 4592.7556 | O5: 4592.7556 | P5: 4592.7556 | Q5: 4592.7556 | R5: 4592.7556 | S5: 4592.7556 | T5: 4592.7556 | U5: 4592.7556 | V5: 4592.7556 | W5: 4592.7556 | X5: 4592.7556 | Y5: 4592.7556 | Z5: 4592.7556 | AA5: 4592.7556 | AB5: 5.3475 | AC5: 5.3475 | AD5: 5.3475 | AE5: 5.3475 | AF5: 5.3475 | AG5: 5.3475 | AH5: 5.3475 | AI5: 5.3475 | AJ5: 5.3475 | AK5: 5.3475 | AL5: 5.3475 | AM5: 5.3475 | AN5: 5.3475 | AO5: 5.3475 | AP5: 5.3475 | AQ5: 5.3475 | AR5: 5.3475 | AS5: 5.3475 | AT5: 5.3475 | AU5: 5.3475 | AV5: 5.3475 | AW5: 5.3475 | AX5: 5.3475 | AY5: 5.3475 | AZ5: 5.3475 | BA5: 11.1005 | BB5: 11.1005 | BC5: 11.1005 | BD5: 11.1005 | BE5: 11.1005 | BF5: 11.1005 | BG5: 11.1005 | BH5: 11.1005 | BI5: 11.1005 | BJ5: 11.1005 | BK5: 11.1005 | BL5: 11.1005 | BM5: 11.1005 | BN5: 11.1005 | BO5: 11.1005 | BP5: 11.1005 | BQ5: 11.1005 | BR5: 11.1005 | BS5: 11.1005 | BT5: 11.1005 | BU5: 11.1005 | BV5: 11.1005 | BW5: 11.1005 | BX5: 11.1005 | BY5: 11.1005 | BZ5: =AVERAGE(AB5:AZ5) -> 5.3475 | CA5: =AVERAGE(BA5:BY5) -> 11.1005
A6: =A5+1 -> 3 | B6: 44228 | C6: 3763.3693 | D6: 3763.3693 | E6: 3763.3693 | F6: 3763.3693 | G6: 3763.3693 | H6: 3763.3693 | I6: 3763.3693 | J6: 3763.3693 | K6: 3763.3693 | L6: 3763.3693 | M6: 3763.3693 | N6: 3763.3693 | O6: 3763.3693 | P6: 3763.3693 | Q6: 3763.3693 | R6: 3763.3693 | S6: 3763.3693 | T6: 3763.3693 | U6: 3763.3693 | V6: 3763.3693 | W6: 3763.3693 | X6: 3763.3693 | Y6: 3763.3693 | Z6: 3763.3693 | AA6: 3763.3693 | AB6: 5.8665 | AC6: 5.8665 | AD6: 5.8665 | AE6: 5.8665 | AF6: 5.8665 | AG6: 5.8665 | AH6: 5.8665 | AI6: 5.8665 | AJ6: 5.8665 | AK6: 5.8665 | AL6: 5.8665 | AM6: 5.8665 | AN6: 5.8665 | AO6: 5.8665 | AP6: 5.8665 | AQ6: 5.8665 | AR6: 5.8665 | AS6: 5.8665 | AT6: 5.8665 | AU6: 5.8665 | AV6: 5.8665 | AW6: 5.8665 | AX6: 5.8665 | AY6: 5.8665 | AZ6: 5.8665 | BA6: 11.032 | BB6: 11.032 | BC6: 11.032 | BD6: 11.032 | BE6: 11.032 | BF6: 11.032 | BG6: 11.032 | BH6: 11.032 | BI6: 11.032 | BJ6: 11.032 | BK6: 11.032 | BL6: 11.032 | BM6: 11.032 | BN6: 11.032 | BO6: 11.032 | BP6: 11.032 | BQ6: 11.032 | BR6: 11.032 | BS6: 11.032 | BT6: 11.032 | BU6: 11.032 | BV6: 11.032 | BW6: 11.032 | BX6: 11.032 | BY6: 11.032 | BZ6: =AVERAGE(AB6:AZ6) -> 5.8665 | CA6: =AVERAGE(BA6:BY6) -> 11.032
A7: =A6+1 -> 4 | B7: 44256 | C7: 8711.2803 | D7: 8711.2803 | E7: 8711.2803 | F7: 8711.2803 | G7: 8711.2803 | H7: 8711.2803 | I7: 8711.2803 | J7: 8711.2803 | K7: 8711.2803 | L7: 8711.2803 | M7: 8711.2803 | N7: 8711.2803 | O7: 8711.2803 | P7: 8711.2803 | Q7: 8711.2803 | R7: 8711.2803 | S7: 8711.2803 | T7: 8711.2803 | U7: 8711.2803 | V7: 8711.2803 | W7: 8711.2803 | X7: 8711.2803 | Y7: 8711.2803 | Z7: 8711.2803 | AA7: 8711.2803 | AB7: 6.1485 | AC7: 6.1485 | AD7: 6.1485 | AE7: 6.1485 | AF7: 6.1485 | AG7: 6.1485 | AH7: 6.1485 | AI7: 6.1485 | AJ7: 6.1485 | AK7: 6.1485 | AL7: 6.1485 | AM7: 6.1485 | AN7: 6.1485 | AO7: 6.1485 | AP7: 6.1485 | AQ7: 6.1485 | AR7: 6.1485 | AS7: 6.1485 | AT7: 6.1485 | AU7: 6.1485 | AV7: 6.1485 | AW7: 6.1485 | AX7: 6.1485 | AY7: 6.1485 | AZ7: 6.1485 | BA7: 11.159 | BB7: 11.159 | BC7: 11.159 | BD7: 11.159 | BE7: 11.159 | BF7: 11.159 | BG7: 11.159 | BH7: 11.159 | BI7: 11.159 | BJ7: 11.159 | BK7: 11.159 | BL7: 11.159 | BM7: 11.159 | BN7: 11.159 | BO7: 11.159 | BP7: 11.159 | BQ7: 11.159 | BR7: 11.159 | BS7: 11.159 | BT7: 11.159 | BU7: 11.159 | BV7: 11.159 | BW7: 11.159 | BX7: 11.159 | BY7: 11.159 | BZ7: =AVERAGE(AB7:AZ7) -> 6.1485 | CA7: =AVERAGE(BA7:BY7) -> 11.159
A8: =A7+1 -> 5 | B8: 44287 | C8: 8381.5881 | D8: 8381.5881 | E8: 8381.5881 | F8: 8381.5881 | G8: 8381.5881 | H8: 8381.5881 | I8: 8381.5881 | J8: 8381.5881 | K8: 8381.5881 | L8: 8381.5881 | M8: 8381.5881 | N8: 8381.5881 | O8: 8381.5881 | P8: 8381.5881 | Q8: 8381.5881 | R8: 8381.5881 | S8: 8381.5881 | T8: 8381.5881 | U8: 8381.5881 | V8: 8381.5881 | W8: 8381.5881 | X8: 8381.5881 | Y8: 8381.5881 | Z8: 8381.5881 | AA8: 8381.5881 | AB8: 5.7495 | AC8: 5.7495 | AD8: 5.7495 | AE8: 5.7495 | AF8: 5.7495 | AG8: 5.7495 | AH8: 5.7495 | AI8: 5.7495 | AJ8: 5.7495 | AK8: 5.7495 | AL8: 5.7495 | AM8: 5.7495 | AN8: 5.7495 | AO8: 5.7495 | AP8: 5.7495 | AQ8: 5.7495 | AR8: 5.7495 | AS8: 5.7495 | AT8: 5.7495 | AU8: 5.7495 | AV8: 5.7495 | AW8: 5.7495 | AX8: 5.7495 | AY8: 5.7495 | AZ8: 5.7495 | BA8: 10.8205 | BB8: 10.8205 | BC8: 10.8205 | BD8: 10.8205 | BE8: 10.8205 | BF8: 10.8205 | BG8: 10.8205 | BH8: 10.8205 | BI8: 10.8205 | BJ8: 10.8205 | BK8: 10.8205 | BL8: 10.8205 | BM8: 10.8205 | BN8: 10.8205 | BO8: 10.8205 | BP8: 10.8205 | BQ8: 10.8205 | BR8: 10.8205 | BS8: 10.8205 | BT8: 10.8205 | BU8: 10.8205 | BV8: 10.8205 | BW8: 10.8205 | BX8: 10.8205 | BY8: 10.8205 | BZ8: =AVERAGE(AB8:AZ8) -> 5.7495 | CA8: =AVERAGE(BA8:BY8) -> 10.8205
A9: =A8+1 -> 6 | B9: 44317 | C9: 9784.91 | D9: 9784.91 | E9: 9784.91 | F9: 9784.91 | G9: 9784.91 | H9: 9784.91 | I9: 9784.91 | J9: 9784.91 | K9: 9784.91 | L9: 9784.91 | M9: 9784.91 | N9: 9784.91 | O9: 9784.91 | P9: 9784.91 | Q9: 9784.91 | R9: 9784.91 | S9: 9784.91 | T9: 9784.91 | U9: 9784.91 | V9: 9784.91 | W9: 9784.91 | X9: 9784.91 | Y9: 9784.91 | Z9: 9784.91 | AA9: 9784.91 | AB9: 4.924 | AC9: 4.924 | AD9: 4.924 | AE9: 4.924 | AF9: 4.924 | AG9: 4.924 | AH9: 4.924 | AI9: 4.924 | AJ9: 4.924 | AK9: 4.924 | AL9: 4.924 | AM9: 4.924 | AN9: 4.924 | AO9: 4.924 | AP9: 4.924 | AQ9: 4.924 | AR9: 4.924 | AS9: 4.924 | AT9: 4.924 | AU9: 4.924 | AV9: 4.924 | AW9: 4.924 | AX9: 4.924 | AY9: 4.924 | AZ9: 4.924 | BA9: 11.2455 | BB9: 11.2455 | BC9: 11.2455 | BD9: 11.2455 | BE9: 11.2455 | BF9: 11.2455 | BG9: 11.2455 | BH9: 11.2455 | BI9: 11.2455 | BJ9: 11.2455 | BK9: 11.2455 | BL9: 11.2455 | BM9: 11.2455 | BN9: 11.2455 | BO9: 11.2455 | BP9: 11.2455 | BQ9: 11.2455 | BR9: 11.2455 | BS9: 11.2455 | BT9: 11.2455 | BU9: 11.2455 | BV9: 11.2455 | BW9: 11.2455 | BX9: 11.2455 | BY9: 11.2455 | BZ9: =AVERAGE(AB9:AZ9) -> 4.924 | CA9: =AVERAGE(BA9:BY9) -> 11.2455
A10: =A9+1 -> 7 | B10: 44348 | C10: 9784.91 | D10: 9784.91 | E10: 9784.91 | F10: 9784.91 | G10: 9784.91 | H10: 9784.91 | I10: 9784.91 | J10: 9784.91 | K10: 9784.91 | L10: 9784.91 | M10: 9784.91 | N10: 9784.91 | O10: 9784.91 | P10: 9784.91 | Q10: 9784.91 | R10: 9784.91 | S10: 9784.91 | T10: 9784.91 | U10: 9784.91 | V10: 9784.91 | W10: 9784.91 | X10: 9784.91 | Y10: 9784.91 | Z10: 9784.91 | AA10: 9784.91 | AB10: 4.671 | AC10: 4.671 | AD10: 4.671 | AE10: 4.671 | AF10: 4.671 | AG10: 4.671 | AH10: 4.671 | AI10: 4.671 | AJ10: 4.671 | AK10: 4.671 | AL10: 4.671 | AM10: 4.671 | AN10: 4.671 | AO10: 4.671 | AP10: 4.671 | AQ10: 4.671 | AR10: 4.671 | AS10: 4.671 | AT10: 4.671 | AU10: 4.671 | AV10: 4.671 | AW10: 4.671 | AX10: 4.671 | AY10: 4.671 | AZ10: 4.671 | BA10: 12.095 | BB10: 12.095 | BC10: 12.095 | BD10: 12.095 | BE10: 12.095 | BF10: 12.095 | BG10: 12.095 | BH10: 12.095 | BI10: 12.095 | BJ10: 12.095 | BK10: 12.095 | BL10: 12.095 | BM10: 12.095 | BN10: 12.095 | BO10: 12.095 | BP10: 12.095 | BQ10: 12.095 | BR10: 12.095 | BS10: 12.095 | BT10: 12.095 | BU10: 12.095 | BV10: 12.095 | BW10: 12.095 | BX10: 12.095 | BY10: 12.095 | BZ10: =AVERAGE(AB10:AZ10) -> 4.671 | CA10: =AVERAGE(BA10:BY10) -> 12.095
A11: =A10+1 -> 8 | B11: 44378 | C11: 9784.91 | D11: 9784.91 | E11: 9784.91 | F11: 9784.91 | G11: 9784.91 | H11: 9784.91 | I11: 9784.91 | J11: 9784.91 | K11: 9784.91 | L11: 9784.91 | M11: 9784.91 | N11: 9784.91 | O11: 9784.91 | P11: 9784.91 | Q11: 9784.91 | R11: 9784.91 | S11: 9784.91 | T11: 9784.91 | U11: 9784.91 | V11: 9784.91 | W11: 9784.91 | X11: 9784.91 | Y11: 9784.91 | Z11: 9784.91 | AA11: 9784.91 | AB11: 4.9365 | AC11: 4.9365 | AD11: 4.9365 | AE11: 4.9365 | AF11: 4.9365 | AG11: 4.9365 | AH11: 4.9365 | AI11: 4.9365 | AJ11: 4.9365 | AK11: 4.9365 | AL11: 4.9365 | AM11: 4.9365 | AN11: 4.9365 | AO11: 4.9365 | AP11: 4.9365 | AQ11: 4.9365 | AR11: 4.9365 | AS11: 4.9365 | AT11: 4.9365 | AU11: 4.9365 | AV11: 4.9365 | AW11: 4.9365 | AX11: 4.9365 | AY11: 4.9365 | AZ11: 4.9365 | BA11: 11.693 | BB11: 11.693 | BC11: 11.693 | BD11: 11.693 | BE11: 11.693 | BF11: 11.693 | BG11: 11.693 | BH11: 11.693 | BI11: 11.693 | BJ11: 11.693 | BK11: 11.693 | BL11: 11.693 | BM11: 11.693 | BN11: 11.693 | BO11: 11.693 | BP11: 11.693 | BQ11: 11.693 | BR11: 11.693 | BS11: 11.693 | BT11: 11.693 | BU11: 11.693 | BV11: 11.693 | BW11: 11.693 | BX11: 11.693 | BY11: 11.693 | BZ11: =AVERAGE(AB11:AZ11) -> 4.9365 | CA11: =AVERAGE(BA11:BY11) -> 11.693
A12: =A11+1 -> 9 | B12: 44409 | C12: 9784.91 | D12: 9784.91 | E12: 9784.91 | F12: 9784.91 | G12: 9784.91 | H12: 9784.91 | I12: 9784.91 | J12: 9784.91 | K12: 9784.91 | L12: 9784.91 | M12: 9784.91 | N12: 9784.91 | O12: 9784.91 | P12: 9784.91 | Q12: 9784.91 | R12: 9784.91 | S12: 9784.91 | T12: 9784.91 | U12: 9784.91 | V12: 9784.91 | W12: 9784.91 | X12: 9784.91 | Y12: 9784.91 | Z12: 9784.91 | AA12: 9784.91 | AB12: 4.604 | AC12: 4.604 | AD12: 4.604 | AE12: 4.604 | AF12: 4.604 | AG12: 4.604 | AH12: 4.604 | AI12: 4.604 | AJ12: 4.604 | AK12: 4.604 | AL12: 4.604 | AM12: 4.604 | AN12: 4.604 | AO12: 4.604 | AP12: 4.604 | AQ12: 4.604 | AR12: 4.604 | AS12: 4.604 | AT12: 4.604 | AU12: 4.604 | AV12: 4.604 | AW12: 4.604 | AX12: 4.604 | AY12: 4.604 | AZ12: 4.604 | BA12: 10.5865 | BB12: 10.5865 | BC12: 10.5865 | BD12: 10.5865 | BE12: 10.5865 | BF12: 10.5865 | BG12: 10.5865 | BH12: 10.5865 | BI12: 10.5865 | BJ12: 10.5865 | BK12: 10.5865 | BL12: 10.5865 | BM12: 10.5865 | BN12: 10.5865 | BO12: 10.5865 | BP12: 10.5865 | BQ12: 10.5865 | BR12: 10.5865 | BS12: 10.5865 | BT12: 10.5865 | BU12: 10.5865 | BV12: 10.5865 | BW12: 10.5865 | BX12: 10.5865 | BY12: 10.5865 | BZ12: =AVERAGE(AB12:AZ12) -> 4.604 | CA12: =AVERAGE(BA12:BY12) -> 10.5865
A13: =A12+1 -> 10 | B13: 44440 | C13: 8731.5199 | D13: 8731.5199 | E13: 8731.5199 | F13: 8731.5199 | G13: 8731.5199 | H13: 8731.5199 | I13: 8731.5199 | J13: 8731.5199 | K13: 8731.5199 | L13: 8731.5199 | M13: 8731.5199 | N13: 8731.5199 | O13: 8731.5199 | P13: 8731.5199 | Q13: 8731.5199 | R13: 8731.5199 | S13: 8731.5199 | T13: 8731.5199 | U13: 8731.5199 | V13: 8731.5199 | W13: 8731.5199 | X13: 8731.5199 | Y13: 8731.5199 | Z13: 8731.5199 | AA13: 8731.5199 | AB13: 3.8415 | AC13: 3.8415 | AD13: 3.8415 | AE13: 3.8415 | AF13: 3.8415 | AG13: 3.8415 | AH13: 3.8415 | AI13: 3.8415 | AJ13: 3.8415 | AK13: 3.8415 | AL13: 3.8415 | AM13: 3.8415 | AN13: 3.8415 | AO13: 3.8415 | AP13: 3.8415 | AQ13: 3.8415 | AR13: 3.8415 | AS13: 3.8415 | AT13: 3.8415 | AU13: 3.8415 | AV13: 3.8415 | AW13: 3.8415 | AX13: 3.8415 | AY13: 3.8415 | AZ13: 3.8415 | BA13: 8.532 | BB13: 8.532 | BC13: 8.532 | BD13: 8.532 | BE13: 8.532 | BF13: 8.532 | BG13: 8.532 | BH13: 8.532 | BI13: 8.532 | BJ13: 8.532 | BK13: 8.532 | BL13: 8.532 | BM13: 8.532 | BN13: 8.532 | BO13: 8.532 | BP13: 8.532 | BQ13: 8.532 | BR13: 8.532 | BS13: 8.532 | BT13: 8.532 | BU13: 8.532 | BV13: 8.532 | BW13: 8.532 | BX13: 8.532 | BY13: 8.532 | BZ13: =AVERAGE(AB13:AZ13) -> 3.8415 | CA13: =AVERAGE(BA13:BY13) -> 8.532
A14: =A13+1 -> 11 | B14: 44470 | C14: 9460.9386 | D14: 9460.9386 | E14: 9460.9386 | F14: 9460.9386 | G14: 9460.9386 | H14: 9460.9386 | I14: 9460.9386 | J14: 9460.9386 | K14: 9460.9386 | L14: 9460.9386 | M14: 9460.9386 | N14: 9460.9386 | O14: 9460.9386 | P14: 9460.9386 | Q14: 9460.9386 | R14: 9460.9386 | S14: 9460.9386 | T14: 9460.9386 | U14: 9460.9386 | V14: 9460.9386 | W14: 9460.9386 | X14: 9460.9386 | Y14: 9460.9386 | Z14: 9460.9386 | AA14: 9460.9386 | AB14: 3.66 | AC14: 3.66 | AD14: 3.66 | AE14: 3.66 | AF14: 3.66 | AG14: 3.66 | AH14: 3.66 | AI14: 3.66 | AJ14: 3.66 | AK14: 3.66 | AL14: 3.66 | AM14: 3.66 | AN14: 3.66 | AO14: 3.66 | AP14: 3.66 | AQ14: 3.66 | AR14: 3.66 | AS14: 3.66 | AT14: 3.66 | AU14: 3.66 | AV14: 3.66 | AW14: 3.66 | AX14: 3.66 | AY14: 3.66 | AZ14: 3.66 | BA14: 8.188 | BB14: 8.188 | BC14: 8.188 | BD14: 8.188 | BE14: 8.188 | BF14: 8.188 | BG14: 8.188 | BH14: 8.188 | BI14: 8.188 | BJ14: 8.188 | BK14: 8.188 | BL14: 8.188 | BM14: 8.188 | BN14: 8.188 | BO14: 8.188 | BP14: 8.188 | BQ14: 8.188 | BR14: 8.188 | BS14: 8.188 | BT14: 8.188 | BU14: 8.188 | BV14: 8.188 | BW14: 8.188 | BX14: 8.188 | BY14: 8.188 | BZ14: =AVERAGE(AB14:AZ14) -> 3.66 | CA14: =AVERAGE(BA14:BY14) -> 8.188
A15: =A14+1 -> 12 | B15: 44501 | C15: 9239.0186 | D15: 9239.0186 | E15: 9239.0186 | F15: 9239.0186 | G15: 9239.0186 | H15: 9239.0186 | I15: 9239.0186 | J15: 9239.0186 | K15: 9239.0186 | L15: 9239.0186 | M15: 9239.0186 | N15: 9239.0186 | O15: 9239.0186 | P15: 9239.0186 | Q15: 9239.0186 | R15: 9239.0186 | S15: 9239.0186 | T15: 9239.0186 | U15: 9239.0186 | V15: 9239.0186 | W15: 9239.0186 | X15: 9239.0186 | Y15: 9239.0186 | Z15: 9239.0186 | AA15: 9239.0186 | AB15: 4.1485 | AC15: 4.1485 | AD15: 4.1485 | AE15: 4.1485 | AF15: 4.1485 | AG15: 4.1485 | AH15: 4.1485 | AI15: 4.1485 | AJ15: 4.1485 | AK15: 4.1485 | AL15: 4.1485 | AM15: 4.1485 | AN15: 4.1485 | AO15: 4.1485 | AP15: 4.1485 | AQ15: 4.1485 | AR15: 4.1485 | AS15: 4.1485 | AT15: 4.1485 | AU15: 4.1485 | AV15: 4.1485 | AW15: 4.1485 | AX15: 4.1485 | AY15: 4.1485 | AZ15: 4.1485 | BA15: 9.2525 | BB15: 9.2525 | BC15: 9.2525 | BD15: 9.2525 | BE15: 9.2525 | BF15: 9.2525 | BG15: 9.2525 | BH15: 9.2525 | BI15: 9.2525 | BJ15: 9.2525 | BK15: 9.2525 | BL15: 9.2525 | BM15: 9.2525 | BN15: 9.2525 | BO15: 9.2525 | BP15: 9.2525 | BQ15: 9.2525 | BR15: 9.2525 | BS15: 9.2525 | BT15: 9.2525 | BU15: 9.2525 | BV15: 9.2525 | BW15: 9.2525 | BX15: 9.2525 | BY15: 9.2525 | BZ15: =AVERAGE(AB15:AZ15) -> 4.1485 | CA15: =AVERAGE(BA15:BY15) -> 9.2525
A16: =A15+1 -> 13 | B16: 44531 | C16: 5616.5134 | D16: 5616.5134 | E16: 5616.5134 | F16: 5616.5134 | G16: 5616.5134 | H16: 5616.5134 | I16: 5616.5134 | J16: 5616.5134 | K16: 5616.5134 | L16: 5616.5134 | M16: 5616.5134 | N16: 5616.5134 | O16: 5616.5134 | P16: 5616.5134 | Q16: 5616.5134 | R16: 5616.5134 | S16: 5616.5134 | T16: 5616.5134 | U16: 5616.5134 | V16: 5616.5134 | W16: 5616.5134 | X16: 5616.5134 | Y16: 5616.5134 | Z16: 5616.5134 | AA16: 5616.5134 | AB16: 4.847 | AC16: 4.847 | AD16: 4.847 | AE16: 4.847 | AF16: 4.847 | AG16: 4.847 | AH16: 4.847 | AI16: 4.847 | AJ16: 4.847 | AK16: 4.847 | AL16: 4.847 | AM16: 4.847 | AN16: 4.847 | AO16: 4.847 | AP16: 4.847 | AQ16: 4.847 | AR16: 4.847 | AS16: 4.847 | AT16: 4.847 | AU16: 4.847 | AV16: 4.847 | AW16: 4.847 | AX16: 4.847 | AY16: 4.847 | AZ16: 4.847 | BA16: 10.7655 | BB16: 10.7655 | BC16: 10.7655 | BD16: 10.7655 | BE16: 10.7655 | BF16: 10.7655 | BG16: 10.7655 | BH16: 10.7655 | BI16: 10.7655 | BJ16: 10.7655 | BK16: 10.7655 | BL16: 10.7655 | BM16: 10.7655 | BN16: 10.7655 | BO16: 10.7655 | BP16: 10.7655 | BQ16: 10.7655 | BR16: 10.7655 | BS16: 10.7655 | BT16: 10.7655 | BU16: 10.7655 | BV16: 10.7655 | BW16: 10.7655 | BX16: 10.7655 | BY16: 10.7655 | BZ16: =AVERAGE(AB16:AZ16) -> 4.847 | CA16: =AVERAGE(BA16:BY16) -> 10.7655
... A364: =A363+1 -> 361 | B364: 55123 | C364: 4914.45 | D364: 6216.7974 | E364: 6258.731 | F364: 6577.9938 | G364: 9784.91 | H364: 9120.6902 | I364: 3944.7024 | J364: 4968.0427 | K364: 8021.1256 | L364: 6281.149 | M364: 6204.442 | N364: 9433.8317 | O364: 4460.9651 | P364: 9784.91 | Q364: 8386.9054 | R364: 5815.479 | S364: 5326.9918 | T364: 8568.111 | U364: 7291.7656 | V364: 4254.2024 | W364: 7347.5361 | X364: 6964.2173 | Y364: 7848.5514 | Z364: 6945.9337 | AA364: 7753.1338 | AB364: 4.7285 | AC364: 4.85 | AD364: 5.09 | AE364: 4.7285 | AF364: 4.7285 | AG364: 4.78 | AH364: 4.7285 | AI364: 4.99 | AJ364: 5.03 | AK364: 4.7285 | AL364: 5.22 | AM364: 4.81 | AN364: 5.2 | AO364: 4.7285 | AP364: 4.7285 | AQ364: 4.87 | AR364: 5.39 | AS364: 4.7285 | AT364: 4.7285 | AU364: 5.17 | AV364: 4.7285 | AW364: 4.7285 | AX364: 4.79 | AY364: 4.7285 | AZ364: 4.811 | BA364: 11.18 | BB364: 10.048 | BC364: 10.17 | BD364: 10.048 | BE364: 10.048 | BF364: 10.048 | BG364: 10.048 | BH364: 11.11 | BI364: 10.048 | BJ364: 10.96 | BK364: 10.048 | BL364: 10.048 | BM364: 10.63 | BN364: 10.048 | BO364: 10.048 | BP364: 10.4 | BQ364: 11.51 | BR364: 10.048 | BS364: 10.61 | BT364: 10.88 | BU364: 10.048 | BV364: 10.051111 | BW364: 10.048 | BX364: 10.058 | BY364: 10.048 | BZ364: =AVERAGE(AB364:AZ364) -> 4.86972 | CA364: =AVERAGE(BA364:BY364) -> 10.329244
A365: =A364+1 -> 362 | C365: 7991.3311 | D365: 7302.4784 | E365: 7492.5049 | F365: 7455.5379 | G365: 7337.694 | H365: 7432.0474 | I365: 7562.8536 | J365: 7583.1706 | K365: 7414.1231 | L365: 7364.8824 | M365: 7628.8077 | N365: 7388.6434 | O365: 7486.6623 | P365: 7560.2927 | Q365: 7447.7973 | R365: 7347.7261 | S365: 7427.4155 | T365: 7412.6223 | U365: 7574.545 | V365: 7463.6973 | W365: 7634.6397 | X365: 7645.7834 | Y365: 7591.4141 | Z365: 7594.6236 | AA365: 7655.0354
A366: =A365+1 -> 363
A367: =A366+1 -> 364 | C367: =C365/E365 -> 1.0665767 | F367: =MAX(F5:F366) -> 9784.91
A368: =A367+1 -> 365
A369: =A368+1 -> 366
A370: =A369+1 -> 367
A371: =A370+1 -> 368 | C371: =C3 -> 1 | D371: =D3 -> 2 | E371: =E3 -> 3 | F371: =F3 -> 4 | G371: =G3 -> 5 | H371: =H3 -> 6 | I371: =I3 -> 7 | J371: =J3 -> 8 | ... BY371: =BY3 -> 25
A372: =A371+1 -> 369 | C372: =CONCATENATE("Control.Aportes[",C371,"]:x") -> Control.Aportes[1]:x | D372: =CONCATENATE("Control.Aportes[",D371,"]:x") -> Control.Aportes[2]:x | E372: =CONCATENATE("Control.Aportes[",E371,"]:x") -> Control.Aportes[3]:x | F372: =CONCATENATE("Control.Aportes[",F371,"]:x") -> Control.Aportes[4]:x | G372: =CONCATENATE("Control.Aportes[",G371,"]:x") -> Control.Aportes[5]:x | H372: =CONCATENATE("Control.Aportes[",H371,"]:x") -> Control.Aportes[6]:x | I372: =CONCATENATE("Control.Aportes[",I371,"]:x") -> Control.Aportes[7]:x | J372: =CONCATENATE("Control.Aportes[",J371,"]:x") -> Control.Aportes[8]:x | ... AA372: =CONCATENATE("Control.Aportes[",AA371,"]:x") -> Control.Aportes[25]:x | AB372: =CONCATENATE("Control.Radiacion[",AB371,"]:x") -> Control.Radiacion[1]:x | AC372: =CONCATENATE("Control.Radiacion[",AC371,"]:x") -> Control.Radiacion[2]:x | AD372: =CONCATENATE("Control.Radiacion[",AD371,"]:x") -> Control.Radiacion[3]:x | AE372: =CONCATENATE("Control.Radiacion[",AE371,"]:x") -> Control.Radiacion[4]:x | AF372: =CONCATENATE("Control.Radiacion[",AF371,"]:x") -> Control.Radiacion[5]:x | AG372: =CONCATENATE("Control.Radiacion[",AG371,"]:x") -> Control.Radiacion[6]:x | AH372: =CONCATENATE("Control.Radiacion[",AH371,"]:x") -> Control.Radiacion[7]:x | AI372: =CONCATENATE("Control.Radiacion[",AI371,"]:x") -> Control.Radiacion[8]:x | ... AZ372: =CONCATENATE("Control.Radiacion[",AZ371,"]:x") -> Control.Radiacion[25]:x | BA372: =CONCATENATE("Control.Viento[",BA371,"]:x") -> Control.Viento[1]:x | BB372: =CONCATENATE("Control.Viento[",BB371,"]:x") -> Control.Viento[2]:x | BC372: =CONCATENATE("Control.Viento[",BC371,"]:x") -> Control.Viento[3]:x | BD372: =CONCATENATE("Control.Viento[",BD371,"]:x") -> Control.Viento[4]:x | BE372: =CONCATENATE("Control.Viento[",BE371,"]:x") -> Control.Viento[5]:x | BF372: =CONCATENATE("Control.Viento[",BF371,"]:x") -> Control.Viento[6]:x | BG372: =CONCATENATE("Control.Viento[",BG371,"]:x") -> Control.Viento[7]:x | BH372: =CONCATENATE("Control.Viento[",BH371,"]:x") -> Control.Viento[8]:x | ... BY372: =CONCATENATE("Control.Viento[",BY371,"]:x") -> Control.Viento[25]:x
A373: =A372+1 -> 370 | B373: 44197 | C373: 1 | D373: 1 | E373: 1 | F373: 1 | G373: 1 | H373: 1 | I373: 1 | J373: 1 | K373: 1 | L373: 1 | M373: 1 | N373: 1 | O373: 1 | P373: 1 | Q373: 1 | R373: 1 | S373: 1 | T373: 1 | U373: 1 | V373: 1 | W373: 1 | X373: 1 | Y373: 1 | Z373: 1 | AA373: 1 | AB373: 1 | AC373: 1 | AD373: 1 | AE373: 1 | AF373: 1 | AG373: 1 | AH373: 1 | AI373: 1 | AJ373: 1 | AK373: 1 | AL373: 1 | AM373: 1 | AN373: 1 | AO373: 1 | AP373: 1 | AQ373: 1 | AR373: 1 | AS373: 1 | AT373: 1 | AU373: 1 | AV373: 1 | AW373: 1 | AX373: 1 | AY373: 1 | AZ373: 1 | BA373: 1 | BB373: 1 | BC373: 1 | BD373: 1 | BE373: 1 | BF373: 1 | BG373: 1 | BH373: 1 | BI373: 1 | BJ373: 1 | BK373: 1 | BL373: 1 | BM373: 1 | BN373: 1 | BO373: 1 | BP373: 1 | BQ373: 1 | BR373: 1 | BS373: 1 | BT373: 1 | BU373: 1 | BV373: 1 | BW373: 1 | BX373: 1 | BY373: 1
A374: =A373+1 -> 371 | B374: 44228 | C374: 2 | D374: 2 | E374: 2 | F374: 2 | G374: 2 | H374: 2 | I374: 2 | J374: 2 | K374: 2 | L374: 2 | M374: 2 | N374: 2 | O374: 2 | P374: 2 | Q374: 2 | R374: 2 | S374: 2 | T374: 2 | U374: 2 | V374: 2 | W374: 2 | X374: 2 | Y374: 2 | Z374: 2 | AA374: 2 | AB374: 2 | AC374: 2 | AD374: 2 | AE374: 2 | AF374: 2 | AG374: 2 | AH374: 2 | AI374: 2 | AJ374: 2 | AK374: 2 | AL374: 2 | AM374: 2 | AN374: 2 | AO374: 2 | AP374: 2 | AQ374: 2 | AR374: 2 | AS374: 2 | AT374: 2 | AU374: 2 | AV374: 2 | AW374: 2 | AX374: 2 | AY374: 2 | AZ374: 2 | BA374: 2 | BB374: 2 | BC374: 2 | BD374: 2 | BE374: 2 | BF374: 2 | BG374: 2 | BH374: 2 | BI374: 2 | BJ374: 2 | BK374: 2 | BL374: 2 | BM374: 2 | BN374: 2 | BO374: 2 | BP374: 2 | BQ374: 2 | BR374: 2 | BS374: 2 | BT374: 2 | BU374: 2 | BV374: 2 | BW374: 2 | BX374: 2 | BY374: 2
A375: =A374+1 -> 372 | B375: 44256 | C375: 3 | D375: 3 | E375: 3 | F375: 3 | G375: 3 | H375: 3 | I375: 3 | J375: 3 | K375: 3 | L375: 3 | M375: 3 | N375: 3 | O375: 3 | P375: 3 | Q375: 3 | R375: 3 | S375: 3 | T375: 3 | U375: 3 | V375: 3 | W375: 3 | X375: 3 | Y375: 3 | Z375: 3 | AA375: 3 | AB375: 3 | AC375: 3 | AD375: 3 | AE375: 3 | AF375: 3 | AG375: 3 | AH375: 3 | AI375: 3 | AJ375: 3 | AK375: 3 | AL375: 3 | AM375: 3 | AN375: 3 | AO375: 3 | AP375: 3 | AQ375: 3 | AR375: 3 | AS375: 3 | AT375: 3 | AU375: 3 | AV375: 3 | AW375: 3 | AX375: 3 | AY375: 3 | AZ375: 3 | BA375: 3 | BB375: 3 | BC375: 3 | BD375: 3 | BE375: 3 | BF375: 3 | BG375: 3 | BH375: 3 | BI375: 3 | BJ375: 3 | BK375: 3 | BL375: 3 | BM375: 3 | BN375: 3 | BO375: 3 | BP375: 3 | BQ375: 3 | BR375: 3 | BS375: 3 | BT375: 3 | BU375: 3 | BV375: 3 | BW375: 3 | BX375: 3 | BY375: 3
A376: =A375+1 -> 373 | B376: 44287 | C376: 4 | D376: 4 | E376: 4 | F376: 4 | G376: 4 | H376: 4 | I376: 4 | J376: 4 | K376: 4 | L376: 4 | M376: 4 | N376: 4 | O376: 4 | P376: 4 | Q376: 4 | R376: 4 | S376: 4 | T376: 4 | U376: 4 | V376: 4 | W376: 4 | X376: 4 | Y376: 4 | Z376: 4 | AA376: 4 | AB376: 4 | AC376: 4 | AD376: 4 | AE376: 4 | AF376: 4 | AG376: 4 | AH376: 4 | AI376: 4 | AJ376: 4 | AK376: 4 | AL376: 4 | AM376: 4 | AN376: 4 | AO376: 4 | AP376: 4 | AQ376: 4 | AR376: 4 | AS376: 4 | AT376: 4 | AU376: 4 | AV376: 4 | AW376: 4 | AX376: 4 | AY376: 4 | AZ376: 4 | BA376: 4 | BB376: 4 | BC376: 4 | BD376: 4 | BE376: 4 | BF376: 4 | BG376: 4 | BH376: 4 | BI376: 4 | BJ376: 4 | BK376: 4 | BL376: 4 | BM376: 4 | BN376: 4 | BO376: 4 | BP376: 4 | BQ376: 4 | BR376: 4 | BS376: 4 | BT376: 4 | BU376: 4 | BV376: 4 | BW376: 4 | BX376: 4 | BY376: 4
A377: =A376+1 -> 374 | B377: 44317 | C377: 5 | D377: 5 | E377: 5 | F377: 5 | G377: 5 | H377: 5 | I377: 5 | J377: 5 | K377: 5 | L377: 5 | M377: 5 | N377: 5 | O377: 5 | P377: 5 | Q377: 5 | R377: 5 | S377: 5 | T377: 5 | U377: 5 | V377: 5 | W377: 5 | X377: 5 | Y377: 5 | Z377: 5 | AA377: 5 | AB377: 5 | AC377: 5 | AD377: 5 | AE377: 5 | AF377: 5 | AG377: 5 | AH377: 5 | AI377: 5 | AJ377: 5 | AK377: 5 | AL377: 5 | AM377: 5 | AN377: 5 | AO377: 5 | AP377: 5 | AQ377: 5 | AR377: 5 | AS377: 5 | AT377: 5 | AU377: 5 | AV377: 5 | AW377: 5 | AX377: 5 | AY377: 5 | AZ377: 5 | BA377: 5 | BB377: 5 | BC377: 5 | BD377: 5 | BE377: 5 | BF377: 5 | BG377: 5 | BH377: 5 | BI377: 5 | BJ377: 5 | BK377: 5 | BL377: 5 | BM377: 5 | BN377: 5 | BO377: 5 | BP377: 5 | BQ377: 5 | BR377: 5 | BS377: 5 | BT377: 5 | BU377: 5 | BV377: 5 | BW377: 5 | BX377: 5 | BY377: 5
A378: =A377+1 -> 375 | B378: 44348 | C378: 6 | D378: 6 | E378: 6 | F378: 6 | G378: 6 | H378: 6 | I378: 6 | J378: 6 | K378: 6 | L378: 6 | M378: 6 | N378: 6 | O378: 6 | P378: 6 | Q378: 6 | R378: 6 | S378: 6 | T378: 6 | U378: 6 | V378: 6 | W378: 6 | X378: 6 | Y378: 6 | Z378: 6 | AA378: 6 | AB378: 6 | AC378: 6 | AD378: 6 | AE378: 6 | AF378: 6 | AG378: 6 | AH378: 6 | AI378: 6 | AJ378: 6 | AK378: 6 | AL378: 6 | AM378: 6 | AN378: 6 | AO378: 6 | AP378: 6 | AQ378: 6 | AR378: 6 | AS378: 6 | AT378: 6 | AU378: 6 | AV378: 6 | AW378: 6 | AX378: 6 | AY378: 6 | AZ378: 6 | BA378: 6 | BB378: 6 | BC378: 6 | BD378: 6 | BE378: 6 | BF378: 6 | BG378: 6 | BH378: 6 | BI378: 6 | BJ378: 6 | BK378: 6 | BL378: 6 | BM378: 6 | BN378: 6 | BO378: 6 | BP378: 6 | BQ378: 6 | BR378: 6 | BS378: 6 | BT378: 6 | BU378: 6 | BV378: 6 | BW378: 6 | BX378: 6 | BY378: 6
A379: =A378+1 -> 376 | B379: 44378 | C379: 7 | D379: 7 | E379: 7 | F379: 7 | G379: 7 | H379: 7 | I379: 7 | J379: 7 | K379: 7 | L379: 7 | M379: 7 | N379: 7 | O379: 7 | P379: 7 | Q379: 7 | R379: 7 | S379: 7 | T379: 7 | U379: 7 | V379: 7 | W379: 7 | X379: 7 | Y379: 7 | Z379: 7 | AA379: 7 | AB379: 7 | AC379: 7 | AD379: 7 | AE379: 7 | AF379: 7 | AG379: 7 | AH379: 7 | AI379: 7 | AJ379: 7 | AK379: 7 | AL379: 7 | AM379: 7 | AN379: 7 | AO379: 7 | AP379: 7 | AQ379: 7 | AR379: 7 | AS379: 7 | AT379: 7 | AU379: 7 | AV379: 7 | AW379: 7 | AX379: 7 | AY379: 7 | AZ379: 7 | BA379: 7 | BB379: 7 | BC379: 7 | BD379: 7 | BE379: 7 | BF379: 7 | BG379: 7 | BH379: 7 | BI379: 7 | BJ379: 7 | BK379: 7 | BL379: 7 | BM379: 7 | BN379: 7 | BO379: 7 | BP379: 7 | BQ379: 7 | BR379: 7 | BS379: 7 | BT379: 7 | BU379: 7 | BV379: 7 | BW379: 7 | BX379: 7 | BY379: 7
A380: =A379+1 -> 377 | B380: 44409 | C380: 8 | D380: 8 | E380: 8 | F380: 8 | G380: 8 | H380: 8 | I380: 8 | J380: 8 | K380: 8 | L380: 8 | M380: 8 | N380: 8 | O380: 8 | P380: 8 | Q380: 8 | R380: 8 | S380: 8 | T380: 8 | U380: 8 | V380: 8 | W380: 8 | X380: 8 | Y380: 8 | Z380: 8 | AA380: 8 | AB380: 8 | AC380: 8 | AD380: 8 | AE380: 8 | AF380: 8 | AG380: 8 | AH380: 8 | AI380: 8 | AJ380: 8 | AK380: 8 | AL380: 8 | AM380: 8 | AN380: 8 | AO380: 8 | AP380: 8 | AQ380: 8 | AR380: 8 | AS380: 8 | AT380: 8 | AU380: 8 | AV380: 8 | AW380: 8 | AX380: 8 | AY380: 8 | AZ380: 8 | BA380: 8 | BB380: 8 | BC380: 8 | BD380: 8 | BE380: 8 | BF380: 8 | BG380: 8 | BH380: 8 | BI380: 8 | BJ380: 8 | BK380: 8 | BL380: 8 | BM380: 8 | BN380: 8 | BO380: 8 | BP380: 8 | BQ380: 8 | BR380: 8 | BS380: 8 | BT380: 8 | BU380: 8 | BV380: 8 | BW380: 8 | BX380: 8 | BY380: 8
A381: =A380+1 -> 378 | B381: 44440 | C381: 9 | D381: 9 | E381: 9 | F381: 9 | G381: 9 | H381: 9 | I381: 9 | J381: 9 | K381: 9 | L381: 9 | M381: 9 | N381: 9 | O381: 9 | P381: 9 | Q381: 9 | R381: 9 | S381: 9 | T381: 9 | U381: 9 | V381: 9 | W381: 9 | X381: 9 | Y381: 9 | Z381: 9 | AA381: 9 | AB381: 9 | AC381: 9 | AD381: 9 | AE381: 9 | AF381: 9 | AG381: 9 | AH381: 9 | AI381: 9 | AJ381: 9 | AK381: 9 | AL381: 9 | AM381: 9 | AN381: 9 | AO381: 9 | AP381: 9 | AQ381: 9 | AR381: 9 | AS381: 9 | AT381: 9 | AU381: 9 | AV381: 9 | AW381: 9 | AX381: 9 | AY381: 9 | AZ381: 9 | BA381: 9 | BB381: 9 | BC381: 9 | BD381: 9 | BE381: 9 | BF381: 9 | BG381: 9 | BH381: 9 | BI381: 9 | BJ381: 9 | BK381: 9 | BL381: 9 | BM381: 9 | BN381: 9 | BO381: 9 | BP381: 9 | BQ381: 9 | BR381: 9 | BS381: 9 | BT381: 9 | BU381: 9 | BV381: 9 | BW381: 9 | BX381: 9 | BY381: 9
A382: =A381+1 -> 379 | B382: 44470 | C382: 10 | D382: 10 | E382: 10 | F382: 10 | G382: 10 | H382: 10 | I382: 10 | J382: 10 | K382: 10 | L382: 10 | M382: 10 | N382: 10 | O382: 10 | P382: 10 | Q382: 10 | R382: 10 | S382: 10 | T382: 10 | U382: 10 | V382: 10 | W382: 10 | X382: 10 | Y382: 10 | Z382: 10 | AA382: 10 | AB382: 10 | AC382: 10 | AD382: 10 | AE382: 10 | AF382: 10 | AG382: 10 | AH382: 10 | AI382: 10 | AJ382: 10 | AK382: 10 | AL382: 10 | AM382: 10 | AN382: 10 | AO382: 10 | AP382: 10 | AQ382: 10 | AR382: 10 | AS382: 10 | AT382: 10 | AU382: 10 | AV382: 10 | AW382: 10 | AX382: 10 | AY382: 10 | AZ382: 10 | BA382: 10 | BB382: 10 | BC382: 10 | BD382: 10 | BE382: 10 | BF382: 10 | BG382: 10 | BH382: 10 | BI382: 10 | BJ382: 10 | BK382: 10 | BL382: 10 | BM382: 10 | BN382: 10 | BO382: 10 | BP382: 10 | BQ382: 10 | BR382: 10 | BS382: 10 | BT382: 10 | BU382: 10 | BV382: 10 | BW382: 10 | BX382: 10 | BY382: 10
A383: =A382+1 -> 380 | B383: 44501 | C383: 11 | D383: 11 | E383: 11 | F383: 11 | G383: 11 | H383: 11 | I383: 11 | J383: 11 | K383: 11 | L383: 11 | M383: 11 | N383: 11 | O383: 11 | P383: 11 | Q383: 11 | R383: 11 | S383: 11 | T383: 11 | U383: 11 | V383: 11 | W383: 11 | X383: 11 | Y383: 11 | Z383: 11 | AA383: 11 | AB383: 11 | AC383: 11 | AD383: 11 | AE383: 11 | AF383: 11 | AG383: 11 | AH383: 11 | AI383: 11 | AJ383: 11 | AK383: 11 | AL383: 11 | AM383: 11 | AN383: 11 | AO383: 11 | AP383: 11 | AQ383: 11 | AR383: 11 | AS383: 11 | AT383: 11 | AU383: 11 | AV383: 11 | AW383: 11 | AX383: 11 | AY383: 11 | AZ383: 11 | BA383: 11 | BB383: 11 | BC383: 11 | BD383: 11 | BE383: 11 | BF383: 11 | BG383: 11 | BH383: 11 | BI383: 11 | BJ383: 11 | BK383: 11 | BL383: 11 | BM383: 11 | BN383: 11 | BO383: 11 | BP383: 11 | BQ383: 11 | BR383: 11 | BS383: 11 | BT383: 11 | BU383: 11 | BV383: 11 | BW383: 11 | BX383: 11 | BY383: 11
A384: =A383+1 -> 381 | B384: 44531 | C384: 12 | D384: 12 | E384: 12 | F384: 12 | G384: 12 | H384: 12 | I384: 12 | J384: 12 | K384: 12 | L384: 12 | M384: 12 | N384: 12 | O384: 12 | P384: 12 | Q384: 12 | R384: 12 | S384: 12 | T384: 12 | U384: 12 | V384: 12 | W384: 12 | X384: 12 | Y384: 12 | Z384: 12 | AA384: 12 | AB384: 12 | AC384: 12 | AD384: 12 | AE384: 12 | AF384: 12 | AG384: 12 | AH384: 12 | AI384: 12 | AJ384: 12 | AK384: 12 | AL384: 12 | AM384: 12 | AN384: 12 | AO384: 12 | AP384: 12 | AQ384: 12 | AR384: 12 | AS384: 12 | AT384: 12 | AU384: 12 | AV384: 12 | AW384: 12 | AX384: 12 | AY384: 12 | AZ384: 12 | BA384: 12 | BB384: 12 | BC384: 12 | BD384: 12 | BE384: 12 | BF384: 12 | BG384: 12 | BH384: 12 | BI384: 12 | BJ384: 12 | BK384: 12 | BL384: 12 | BM384: 12 | BN384: 12 | BO384: 12 | BP384: 12 | BQ384: 12 | BR384: 12 | BS384: 12 | BT384: 12 | BU384: 12 | BV384: 12 | BW384: 12 | BX384: 12 | BY384: 12
... A720: =A719+1 -> 717 | B720: 54758 | C720: 348 | D720: 348 | E720: 348 | F720: 348 | G720: 348 | H720: 348 | I720: 348 | J720: 348 | K720: 348 | L720: 348 | M720: 348 | N720: 348 | O720: 348 | P720: 348 | Q720: 348 | R720: 348 | S720: 348 | T720: 348 | U720: 348 | V720: 348 | W720: 348 | X720: 348 | Y720: 348 | Z720: 348 | AA720: 348 | AB720: 348 | AC720: 348 | AD720: 348 | AE720: 348 | AF720: 348 | AG720: 348 | AH720: 348 | AI720: 348 | AJ720: 348 | AK720: 348 | AL720: 348 | AM720: 348 | AN720: 348 | AO720: 348 | AP720: 348 | AQ720: 348 | AR720: 348 | AS720: 348 | AT720: 348 | AU720: 348 | AV720: 348 | AW720: 348 | AX720: 348 | AY720: 348 | AZ720: 348 | BA720: 348 | BB720: 348 | BC720: 348 | BD720: 348 | BE720: 348 | BF720: 348 | BG720: 348 | BH720: 348 | BI720: 348 | BJ720: 348 | BK720: 348 | BL720: 348 | BM720: 348 | BN720: 348 | BO720: 348 | BP720: 348 | BQ720: 348 | BR720: 348 | BS720: 348 | BT720: 348 | BU720: 348 | BV720: 348 | BW720: 348 | BX720: 348 | BY720: 348
B721: 54789 | C721: 349 | D721: 349 | E721: 349 | F721: 349 | G721: 349 | H721: 349 | I721: 349 | J721: 349 | K721: 349 | L721: 349 | M721: 349 | N721: 349 | O721: 349 | P721: 349 | Q721: 349 | R721: 349 | S721: 349 | T721: 349 | U721: 349 | V721: 349 | W721: 349 | X721: 349 | Y721: 349 | Z721: 349 | AA721: 349 | AB721: 349 | AC721: 349 | AD721: 349 | AE721: 349 | AF721: 349 | AG721: 349 | AH721: 349 | AI721: 349 | AJ721: 349 | AK721: 349 | AL721: 349 | AM721: 349 | AN721: 349 | AO721: 349 | AP721: 349 | AQ721: 349 | AR721: 349 | AS721: 349 | AT721: 349 | AU721: 349 | AV721: 349 | AW721: 349 | AX721: 349 | AY721: 349 | AZ721: 349 | BA721: 349 | BB721: 349 | BC721: 349 | BD721: 349 | BE721: 349 | BF721: 349 | BG721: 349 | BH721: 349 | BI721: 349 | BJ721: 349 | BK721: 349 | BL721: 349 | BM721: 349 | BN721: 349 | BO721: 349 | BP721: 349 | BQ721: 349 | BR721: 349 | BS721: 349 | BT721: 349 | BU721: 349 | BV721: 349 | BW721: 349 | BX721: 349 | BY721: 349
B722: 54820 | C722: 350 | D722: 350 | E722: 350 | F722: 350 | G722: 350 | H722: 350 | I722: 350 | J722: 350 | K722: 350 | L722: 350 | M722: 350 | N722: 350 | O722: 350 | P722: 350 | Q722: 350 | R722: 350 | S722: 350 | T722: 350 | U722: 350 | V722: 350 | W722: 350 | X722: 350 | Y722: 350 | Z722: 350 | AA722: 350 | AB722: 350 | AC722: 350 | AD722: 350 | AE722: 350 | AF722: 350 | AG722: 350 | AH722: 350 | AI722: 350 | AJ722: 350 | AK722: 350 | AL722: 350 | AM722: 350 | AN722: 350 | AO722: 350 | AP722: 350 | AQ722: 350 | AR722: 350 | AS722: 350 | AT722: 350 | AU722: 350 | AV722: 350 | AW722: 350 | AX722: 350 | AY722: 350 | AZ722: 350 | BA722: 350 | BB722: 350 | BC722: 350 | BD722: 350 | BE722: 350 | BF722: 350 | BG722: 350 | BH722: 350 | BI722: 350 | BJ722: 350 | BK722: 350 | BL722: 350 | BM722: 350 | BN722: 350 | BO722: 350 | BP722: 350 | BQ722: 350 | BR722: 350 | BS722: 350 | BT722: 350 | BU722: 350 | BV722: 350 | BW722: 350 | BX722: 350 | BY722: 350
...

Sheet Hoja1

Sheet External
C2: 1 | D2: =C2+1 -> 2 | E2: =D2+1 -> 3 | F2: =E2+1 -> 4 | G2: =F2+1 -> 5 | H2: =G2+1 -> 6 | I2: =H2+1 -> 7 | J2: =I2+1 -> 8 | K2: =J2+1 -> 9 | ... EV2: =EU2+1 -> 150
C3: 1 | D3: 1 | E3: =C3+1 -> 2 | F3: =D3+1 -> 2 | G3: =E3+1 -> 3 | H3: =F3+1 -> 3 | I3: =G3+1 -> 4 | J3: =H3+1 -> 4 | K3: =I3+1 -> 5 | L3: =J3+1 -> 5 | ... EV3: =ET3+1 -> 75
C4: =MOD(C2,2) -> 1 | D4: =MOD(D2,2) -> 0 | E4: =MOD(E2,2) -> 1 | F4: =MOD(F2,2) -> 0 | G4: =MOD(G2,2) -> 1 | H4: =MOD(H2,2) -> 0 | I4: =MOD(I2,2) -> 1 | J4: =MOD(J2,2) -> 0 | ... EV4: =MOD(EV2,2) -> 0
A5: =Datos!A371 -> 368 | B5: 1 | C5: =INDEX(Datos!$C$4:$BY$720,IF(C$4=0,$B5,$B5+$A$5),C$3) -> Control.Aportes[1]:x | D5: =INDEX(Datos!$C$4:$BY$720,IF(D$4=0,$B5,$B5+$A$5),D$3) -> Control.Aportes[1]:y | E5: =INDEX(Datos!$C$4:$BY$720,IF(E$4=0,$B5,$B5+$A$5),E$3) -> Control.Aportes[2]:x | F5: =INDEX(Datos!$C$4:$BY$720,IF(F$4=0,$B5,$B5+$A$5),F$3) -> Control.Aportes[2]:y | G5: =INDEX(Datos!$C$4:$BY$720,IF(G$4=0,$B5,$B5+$A$5),G$3) -> Control.Aportes[3]:x | H5: =INDEX(Datos!$C$4:$BY$720,IF(H$4=0,$B5,$B5+$A$5),H$3) -> Control.Aportes[3]:y | I5: =INDEX(Datos!$C$4:$BY$720,IF(I$4=0,$B5,$B5+$A$5),I$3) -> Control.Aportes[4]:x | J5: =INDEX(Datos!$C$4:$BY$720,IF(J$4=0,$B5,$B5+$A$5),J$3) -> Control.Aportes[4]:y | ... EV5: =INDEX(Datos!$C$4:$BY$720,IF(EV$4=0,$B5,$B5+$A$5),EV$3) -> Control.Viento[25]:y
B6: =B5+1 -> 2 | C6: =INDEX(Datos!$C$4:$BY$732,IF(C$4=0,$B6,$B6+$A$5),C$3) -> 1 | D6: =INDEX(Datos!$C$4:$BT$732,IF(D$4=0,$B6,$B6+$A$5),D$3) -> 4592.7556 | E6: =INDEX(Datos!$C$4:$BT$732,IF(E$4=0,$B6,$B6+$A$5),E$3) -> 1 | F6: =INDEX(Datos!$C$4:$BT$732,IF(F$4=0,$B6,$B6+$A$5),F$3) -> 4592.7556 | G6: =INDEX(Datos!$C$4:$BT$732,IF(G$4=0,$B6,$B6+$A$5),G$3) -> 1 | H6: =INDEX(Datos!$C$4:$BT$732,IF(H$4=0,$B6,$B6+$A$5),H$3) -> 4592.7556 | I6: =INDEX(Datos!$C$4:$BT$732,IF(I$4=0,$B6,$B6+$A$5),I$3) -> 1 | J6: =INDEX(Datos!$C$4:$BT$732,IF(J$4=0,$B6,$B6+$A$5),J$3) -> 4592.7556 | K6: =INDEX(Datos!$C$4:$BT$732,IF(K$4=0,$B6,$B6+$A$5),K$3) -> 1 | ... EL6: =INDEX(Datos!$C$4:$BT$732,IF(EL$4=0,$B6,$B6+$A$5),EL$3) -> 11.1005 | EM6: =INDEX(Datos!$C$4:$BY$732,IF(EM$4=0,$B6,$B6+$A$5),EM$3) -> 1 | EN6: =INDEX(Datos!$C$4:$BY$732,IF(EN$4=0,$B6,$B6+$A$5),EN$3) -> 11.1005 | EO6: =INDEX(Datos!$C$4:$BY$732,IF(EO$4=0,$B6,$B6+$A$5),EO$3) -> 1 | EP6: =INDEX(Datos!$C$4:$BY$732,IF(EP$4=0,$B6,$B6+$A$5),EP$3) -> 11.1005 | EQ6: =INDEX(Datos!$C$4:$BY$732,IF(EQ$4=0,$B6,$B6+$A$5),EQ$3) -> 1 | ER6: =INDEX(Datos!$C$4:$BY$732,IF(ER$4=0,$B6,$B6+$A$5),ER$3) -> 11.1005 | ES6: =INDEX(Datos!$C$4:$BY$732,IF(ES$4=0,$B6,$B6+$A$5),ES$3) -> 1 | ET6: =INDEX(Datos!$C$4:$BY$732,IF(ET$4=0,$B6,$B6+$A$5),ET$3) -> 11.1005 | ... EV6: =INDEX(Datos!$C$4:$BY$732,IF(EV$4=0,$B6,$B6+$A$5),EV$3) -> 11.1005
B7: =B6+1 -> 3 | C7: =INDEX(Datos!$C$4:$BT$732,IF(C$4=0,$B7,$B7+$A$5),C$3) -> 2 | D7: =INDEX(Datos!$C$4:$BT$732,IF(D$4=0,$B7,$B7+$A$5),D$3) -> 3763.3693 | E7: =INDEX(Datos!$C$4:$BT$732,IF(E$4=0,$B7,$B7+$A$5),E$3) -> 2 | F7: =INDEX(Datos!$C$4:$BT$732,IF(F$4=0,$B7,$B7+$A$5),F$3) -> 3763.3693 | G7: =INDEX(Datos!$C$4:$BT$732,IF(G$4=0,$B7,$B7+$A$5),G$3) -> 2 | H7: =INDEX(Datos!$C$4:$BT$732,IF(H$4=0,$B7,$B7+$A$5),H$3) -> 3763.3693 | I7: =INDEX(Datos!$C$4:$BT$732,IF(I$4=0,$B7,$B7+$A$5),I$3) -> 2 | J7: =INDEX(Datos!$C$4:$BT$732,IF(J$4=0,$B7,$B7+$A$5),J$3) -> 3763.3693 | ... EL7: =INDEX(Datos!$C$4:$BT$732,IF(EL$4=0,$B7,$B7+$A$5),EL$3) -> 11.032 | EM7: =INDEX(Datos!$C$4:$BY$732,IF(EM$4=0,$B7,$B7+$A$5),EM$3) -> 2 | EN7: =INDEX(Datos!$C$4:$BY$732,IF(EN$4=0,$B7,$B7+$A$5),EN$3) -> 11.032 | EO7: =INDEX(Datos!$C$4:$BY$732,IF(EO$4=0,$B7,$B7+$A$5),EO$3) -> 2 | EP7: =INDEX(Datos!$C$4:$BY$732,IF(EP$4=0,$B7,$B7+$A$5),EP$3) -> 11.032 | EQ7: =INDEX(Datos!$C$4:$BY$732,IF(EQ$4=0,$B7,$B7+$A$5),EQ$3) -> 2 | ER7: =INDEX(Datos!$C$4:$BY$732,IF(ER$4=0,$B7,$B7+$A$5),ER$3) -> 11.032 | ES7: =INDEX(Datos!$C$4:$BY$732,IF(ES$4=0,$B7,$B7+$A$5),ES$3) -> 2 | ET7: =INDEX(Datos!$C$4:$BY$732,IF(ET$4=0,$B7,$B7+$A$5),ET$3) -> 11.032 | ... EV7: =INDEX(Datos!$C$4:$BY$732,IF(EV$4=0,$B7,$B7+$A$5),EV$3) -> 11.032
B8: =B7+1 -> 4 | C8: =INDEX(Datos!$C$4:$BT$732,IF(C$4=0,$B8,$B8+$A$5),C$3) -> 3 | D8: =INDEX(Datos!$C$4:$BT$732,IF(D$4=0,$B8,$B8+$A$5),D$3) -> 8711.2803 | E8: =INDEX(Datos!$C$4:$BT$732,IF(E$4=0,$B8,$B8+$A$5),E$3) -> 3 | F8: =INDEX(Datos!$C$4:$BT$732,IF(F$4=0,$B8,$B8+$A$5),F$3) -> 8711.2803 | G8: =INDEX(Datos!$C$4:$BT$732,IF(G$4=0,$B8,$B8+$A$5),G$3) -> 3 | H8: =INDEX(Datos!$C$4:$BT$732,IF(H$4=0,$B8,$B8+$A$5),H$3) -> 8711.2803 | I8: =INDEX(Datos!$C$4:$BT$732,IF(I$4=0,$B8,$B8+$A$5),I$3) -> 3 | J8: =INDEX(Datos!$C$4:$BT$732,IF(J$4=0,$B8,$B8+$A$5),J$3) -> 8711.2803 | ... EL8: =INDEX(Datos!$C$4:$BT$732,IF(EL$4=0,$B8,$B8+$A$5),EL$3) -> 11.159 | EM8: =INDEX(Datos!$C$4:$BY$732,IF(EM$4=0,$B8,$B8+$A$5),EM$3) -> 3 | EN8: =INDEX(Datos!$C$4:$BY$732,IF(EN$4=0,$B8,$B8+$A$5),EN$3) -> 11.159 | EO8: =INDEX(Datos!$C$4:$BY$732,IF(EO$4=0,$B8,$B8+$A$5),EO$3) -> 3 | EP8: =INDEX(Datos!$C$4:$BY$732,IF(EP$4=0,$B8,$B8+$A$5),EP$3) -> 11.159 | EQ8: =INDEX(Datos!$C$4:$BY$732,IF(EQ$4=0,$B8,$B8+$A$5),EQ$3) -> 3 | ER8: =INDEX(Datos!$C$4:$BY$732,IF(ER$4=0,$B8,$B8+$A$5),ER$3) -> 11.159 | ES8: =INDEX(Datos!$C$4:$BY$732,IF(ES$4=0,$B8,$B8+$A$5),ES$3) -> 3 | ET8: =INDEX(Datos!$C$4:$BY$732,IF(ET$4=0,$B8,$B8+$A$5),ET$3) -> 11.159 | ... EV8: =INDEX(Datos!$C$4:$BY$732,IF(EV$4=0,$B8,$B8+$A$5),EV$3) -> 11.159
B9: =B8+1 -> 5 | C9: =INDEX(Datos!$C$4:$BT$732,IF(C$4=0,$B9,$B9+$A$5),C$3) -> 4 | D9: =INDEX(Datos!$C$4:$BT$732,IF(D$4=0,$B9,$B9+$A$5),D$3) -> 8381.5881 | E9: =INDEX(Datos!$C$4:$BT$732,IF(E$4=0,$B9,$B9+$A$5),E$3) -> 4 | F9: =INDEX(Datos!$C$4:$BT$732,IF(F$4=0,$B9,$B9+$A$5),F$3) -> 8381.5881 | G9: =INDEX(Datos!$C$4:$BT$732,IF(G$4=0,$B9,$B9+$A$5),G$3) -> 4 | H9: =INDEX(Datos!$C$4:$BT$732,IF(H$4=0,$B9,$B9+$A$5),H$3) -> 8381.5881 | I9: =INDEX(Datos!$C$4:$BT$732,IF(I$4=0,$B9,$B9+$A$5),I$3) -> 4 | J9: =INDEX(Datos!$C$4:$BT$732,IF(J$4=0,$B9,$B9+$A$5),J$3) -> 8381.5881 | ... EL9: =INDEX(Datos!$C$4:$BT$732,IF(EL$4=0,$B9,$B9+$A$5),EL$3) -> 10.8205 | EM9: =INDEX(Datos!$C$4:$BY$732,IF(EM$4=0,$B9,$B9+$A$5),EM$3) -> 4 | EN9: =INDEX(Datos!$C$4:$BY$732,IF(EN$4=0,$B9,$B9+$A$5),EN$3) -> 10.8205 | EO9: =INDEX(Datos!$C$4:$BY$732,IF(EO$4=0,$B9,$B9+$A$5),EO$3) -> 4 | EP9: =INDEX(Datos!$C$4:$BY$732,IF(EP$4=0,$B9,$B9+$A$5),EP$3) -> 10.8205 | EQ9: =INDEX(Datos!$C$4:$BY$732,IF(EQ$4=0,$B9,$B9+$A$5),EQ$3) -> 4 | ER9: =INDEX(Datos!$C$4:$BY$732,IF(ER$4=0,$B9,$B9+$A$5),ER$3) -> 10.8205 | ES9: =INDEX(Datos!$C$4:$BY$732,IF(ES$4=0,$B9,$B9+$A$5),ES$3) -> 4 | ET9: =INDEX(Datos!$C$4:$BY$732,IF(ET$4=0,$B9,$B9+$A$5),ET$3) -> 10.8205 | ... EV9: =INDEX(Datos!$C$4:$BY$732,IF(EV$4=0,$B9,$B9+$A$5),EV$3) -> 10.8205
B10: =B9+1 -> 6 | C10: =INDEX(Datos!$C$4:$BT$732,IF(C$4=0,$B10,$B10+$A$5),C$3) -> 5 | D10: =INDEX(Datos!$C$4:$BT$732,IF(D$4=0,$B10,$B10+$A$5),D$3) -> 9784.91 | E10: =INDEX(Datos!$C$4:$BT$732,IF(E$4=0,$B10,$B10+$A$5),E$3) -> 5 | F10: =INDEX(Datos!$C$4:$BT$732,IF(F$4=0,$B10,$B10+$A$5),F$3) -> 9784.91 | G10: =INDEX(Datos!$C$4:$BT$732,IF(G$4=0,$B10,$B10+$A$5),G$3) -> 5 | H10: =INDEX(Datos!$C$4:$BT$732,IF(H$4=0,$B10,$B10+$A$5),H$3) -> 9784.91 | I10: =INDEX(Datos!$C$4:$BT$732,IF(I$4=0,$B10,$B10+$A$5),I$3) -> 5 | J10: =INDEX(Datos!$C$4:$BT$732,IF(J$4=0,$B10,$B10+$A$5),J$3) -> 9784.91 | ... EL10: =INDEX(Datos!$C$4:$BT$732,IF(EL$4=0,$B10,$B10+$A$5),EL$3) -> 11.2455 | EM10: =INDEX(Datos!$C$4:$BY$732,IF(EM$4=0,$B10,$B10+$A$5),EM$3) -> 5 | EN10: =INDEX(Datos!$C$4:$BY$732,IF(EN$4=0,$B10,$B10+$A$5),EN$3) -> 11.2455 | EO10: =INDEX(Datos!$C$4:$BY$732,IF(EO$4=0,$B10,$B10+$A$5),EO$3) -> 5 | EP10: =INDEX(Datos!$C$4:$BY$732,IF(EP$4=0,$B10,$B10+$A$5),EP$3) -> 11.2455 | EQ10: =INDEX(Datos!$C$4:$BY$732,IF(EQ$4=0,$B10,$B10+$A$5),EQ$3) -> 5 | ER10: =INDEX(Datos!$C$4:$BY$732,IF(ER$4=0,$B10,$B10+$A$5),ER$3) -> 11.2455 | ES10: =INDEX(Datos!$C$4:$BY$732,IF(ES$4=0,$B10,$B10+$A$5),ES$3) -> 5 | ET10: =INDEX(Datos!$C$4:$BY$732,IF(ET$4=0,$B10,$B10+$A$5),ET$3) -> 11.2455 | ... EV10: =INDEX(Datos!$C$4:$BY$732,IF(EV$4=0,$B10,$B10+$A$5),EV$3) -> 11.2455
B11: =B10+1 -> 7 | C11: =INDEX(Datos!$C$4:$BT$732,IF(C$4=0,$B11,$B11+$A$5),C$3) -> 6 | D11: =INDEX(Datos!$C$4:$BT$732,IF(D$4=0,$B11,$B11+$A$5),D$3) -> 9784.91 | E11: =INDEX(Datos!$C$4:$BT$732,IF(E$4=0,$B11,$B11+$A$5),E$3) -> 6 | F11: =INDEX(Datos!$C$4:$BT$732,IF(F$4=0,$B11,$B11+$A$5),F$3) -> 9784.91 | G11: =INDEX(Datos!$C$4:$BT$732,IF(G$4=0,$B11,$B11+$A$5),G$3) -> 6 | H11: =INDEX(Datos!$C$4:$BT$732,IF(H$4=0,$B11,$B11+$A$5),H$3) -> 9784.91 | I11: =INDEX(Datos!$C$4:$BT$732,IF(I$4=0,$B11,$B11+$A$5),I$3) -> 6 | J11: =INDEX(Datos!$C$4:$BT$732,IF(J$4=0,$B11,$B11+$A$5),J$3) -> 9784.91 | ... EL11: =INDEX(Datos!$C$4:$BT$732,IF(EL$4=0,$B11,$B11+$A$5),EL$3) -> 12.095 | EM11: =INDEX(Datos!$C$4:$BY$732,IF(EM$4=0,$B11,$B11+$A$5),EM$3) -> 6 | EN11: =INDEX(Datos!$C$4:$BY$732,IF(EN$4=0,$B11,$B11+$A$5),EN$3) -> 12.095 | EO11: =INDEX(Datos!$C$4:$BY$732,IF(EO$4=0,$B11,$B11+$A$5),EO$3) -> 6 | EP11: =INDEX(Datos!$C$4:$BY$732,IF(EP$4=0,$B11,$B11+$A$5),EP$3) -> 12.095 | EQ11: =INDEX(Datos!$C$4:$BY$732,IF(EQ$4=0,$B11,$B11+$A$5),EQ$3) -> 6 | ER11: =INDEX(Datos!$C$4:$BY$732,IF(ER$4=0,$B11,$B11+$A$5),ER$3) -> 12.095 | ES11: =INDEX(Datos!$C$4:$BY$732,IF(ES$4=0,$B11,$B11+$A$5),ES$3) -> 6 | ET11: =INDEX(Datos!$C$4:$BY$732,IF(ET$4=0,$B11,$B11+$A$5),ET$3) -> 12.095 | ... EV11: =INDEX(Datos!$C$4:$BY$732,IF(EV$4=0,$B11,$B11+$A$5),EV$3) -> 12.095
B12: =B11+1 -> 8 | C12: =INDEX(Datos!$C$4:$BT$732,IF(C$4=0,$B12,$B12+$A$5),C$3) -> 7 | D12: =INDEX(Datos!$C$4:$BT$732,IF(D$4=0,$B12,$B12+$A$5),D$3) -> 9784.91 | E12: =INDEX(Datos!$C$4:$BT$732,IF(E$4=0,$B12,$B12+$A$5),E$3) -> 7 | F12: =INDEX(Datos!$C$4:$BT$732,IF(F$4=0,$B12,$B12+$A$5),F$3) -> 9784.91 | G12: =INDEX(Datos!$C$4:$BT$732,IF(G$4=0,$B12,$B12+$A$5),G$3) -> 7 | H12: =INDEX(Datos!$C$4:$BT$732,IF(H$4=0,$B12,$B12+$A$5),H$3) -> 9784.91 | I12: =INDEX(Datos!$C$4:$BT$732,IF(I$4=0,$B12,$B12+$A$5),I$3) -> 7 | J12: =INDEX(Datos!$C$4:$BT$732,IF(J$4=0,$B12,$B12+$A$5),J$3) -> 9784.91 | ... EL12: =INDEX(Datos!$C$4:$BT$732,IF(EL$4=0,$B12,$B12+$A$5),EL$3) -> 11.693 | EM12: =INDEX(Datos!$C$4:$BY$732,IF(EM$4=0,$B12,$B12+$A$5),EM$3) -> 7 | EN12: =INDEX(Datos!$C$4:$BY$732,IF(EN$4=0,$B12,$B12+$A$5),EN$3) -> 11.693 | EO12: =INDEX(Datos!$C$4:$BY$732,IF(EO$4=0,$B12,$B12+$A$5),EO$3) -> 7 | EP12: =INDEX(Datos!$C$4:$BY$732,IF(EP$4=0,$B12,$B12+$A$5),EP$3) -> 11.693 | EQ12: =INDEX(Datos!$C$4:$BY$732,IF(EQ$4=0,$B12,$B12+$A$5),EQ$3) -> 7 | ER12: =INDEX(Datos!$C$4:$BY$732,IF(ER$4=0,$B12,$B12+$A$5),ER$3) -> 11.693 | ES12: =INDEX(Datos!$C$4:$BY$732,IF(ES$4=0,$B12,$B12+$A$5),ES$3) -> 7 | ET12: =INDEX(Datos!$C$4:$BY$732,IF(ET$4=0,$B12,$B12+$A$5),ET$3) -> 11.693 | ... EV12: =INDEX(Datos!$C$4:$BY$732,IF(EV$4=0,$B12,$B12+$A$5),EV$3) -> 11.693
B13: =B12+1 -> 9 | C13: =INDEX(Datos!$C$4:$BT$732,IF(C$4=0,$B13,$B13+$A$5),C$3) -> 8 | D13: =INDEX(Datos!$C$4:$BT$732,IF(D$4=0,$B13,$B13+$A$5),D$3) -> 9784.91 | E13: =INDEX(Datos!$C$4:$BT$732,IF(E$4=0,$B13,$B13+$A$5),E$3) -> 8 | F13: =INDEX(Datos!$C$4:$BT$732,IF(F$4=0,$B13,$B13+$A$5),F$3) -> 9784.91 | G13: =INDEX(Datos!$C$4:$BT$732,IF(G$4=0,$B13,$B13+$A$5),G$3) -> 8 | H13: =INDEX(Datos!$C$4:$BT$732,IF(H$4=0,$B13,$B13+$A$5),H$3) -> 9784.91 | I13: =INDEX(Datos!$C$4:$BT$732,IF(I$4=0,$B13,$B13+$A$5),I$3) -> 8 | J13: =INDEX(Datos!$C$4:$BT$732,IF(J$4=0,$B13,$B13+$A$5),J$3) -> 9784.91 | ... EL13: =INDEX(Datos!$C$4:$BT$732,IF(EL$4=0,$B13,$B13+$A$5),EL$3) -> 10.5865 | EM13: =INDEX(Datos!$C$4:$BY$732,IF(EM$4=0,$B13,$B13+$A$5),EM$3) -> 8 | EN13: =INDEX(Datos!$C$4:$BY$732,IF(EN$4=0,$B13,$B13+$A$5),EN$3) -> 10.5865 | EO13: =INDEX(Datos!$C$4:$BY$732,IF(EO$4=0,$B13,$B13+$A$5),EO$3) -> 8 | EP13: =INDEX(Datos!$C$4:$BY$732,IF(EP$4=0,$B13,$B13+$A$5),EP$3) -> 10.5865 | EQ13: =INDEX(Datos!$C$4:$BY$732,IF(EQ$4=0,$B13,$B13+$A$5),EQ$3) -> 8 | ER13: =INDEX(Datos!$C$4:$BY$732,IF(ER$4=0,$B13,$B13+$A$5),ER$3) -> 10.5865 | ES13: =INDEX(Datos!$C$4:$BY$732,IF(ES$4=0,$B13,$B13+$A$5),ES$3) -> 8 | ET13: =INDEX(Datos!$C$4:$BY$732,IF(ET$4=0,$B13,$B13+$A$5),ET$3) -> 10.5865 | ... EV13: =INDEX(Datos!$C$4:$BY$732,IF(EV$4=0,$B13,$B13+$A$5),EV$3) -> 10.5865
B14: =B13+1 -> 10 | C14: =INDEX(Datos!$C$4:$BT$732,IF(C$4=0,$B14,$B14+$A$5),C$3) -> 9 | D14: =INDEX(Datos!$C$4:$BT$732,IF(D$4=0,$B14,$B14+$A$5),D$3) -> 8731.5199 | E14: =INDEX(Datos!$C$4:$BT$732,IF(E$4=0,$B14,$B14+$A$5),E$3) -> 9 | F14: =INDEX(Datos!$C$4:$BT$732,IF(F$4=0,$B14,$B14+$A$5),F$3) -> 8731.5199 | G14: =INDEX(Datos!$C$4:$BT$732,IF(G$4=0,$B14,$B14+$A$5),G$3) -> 9 | H14: =INDEX(Datos!$C$4:$BT$732,IF(H$4=0,$B14,$B14+$A$5),H$3) -> 8731.5199 | I14: =INDEX(Datos!$C$4:$BT$732,IF(I$4=0,$B14,$B14+$A$5),I$3) -> 9 | J14: =INDEX(Datos!$C$4:$BT$732,IF(J$4=0,$B14,$B14+$A$5),J$3) -> 8731.5199 | ... EL14: =INDEX(Datos!$C$4:$BT$732,IF(EL$4=0,$B14,$B14+$A$5),EL$3) -> 8.532 | EM14: =INDEX(Datos!$C$4:$BY$732,IF(EM$4=0,$B14,$B14+$A$5),EM$3) -> 9 | EN14: =INDEX(Datos!$C$4:$BY$732,IF(EN$4=0,$B14,$B14+$A$5),EN$3) -> 8.532 | EO14: =INDEX(Datos!$C$4:$BY$732,IF(EO$4=0,$B14,$B14+$A$5),EO$3) -> 9 | EP14: =INDEX(Datos!$C$4:$BY$732,IF(EP$4=0,$B14,$B14+$A$5),EP$3) -> 8.532 | EQ14: =INDEX(Datos!$C$4:$BY$732,IF(EQ$4=0,$B14,$B14+$A$5),EQ$3) -> 9 | ER14: =INDEX(Datos!$C$4:$BY$732,IF(ER$4=0,$B14,$B14+$A$5),ER$3) -> 8.532 | ES14: =INDEX(Datos!$C$4:$BY$732,IF(ES$4=0,$B14,$B14+$A$5),ES$3) -> 9 | ET14: =INDEX(Datos!$C$4:$BY$732,IF(ET$4=0,$B14,$B14+$A$5),ET$3) -> 8.532 | ... EV14: =INDEX(Datos!$C$4:$BY$732,IF(EV$4=0,$B14,$B14+$A$5),EV$3) -> 8.532
B15: =B14+1 -> 11 | C15: =INDEX(Datos!$C$4:$BT$732,IF(C$4=0,$B15,$B15+$A$5),C$3) -> 10 | D15: =INDEX(Datos!$C$4:$BT$732,IF(D$4=0,$B15,$B15+$A$5),D$3) -> 9460.9386 | E15: =INDEX(Datos!$C$4:$BT$732,IF(E$4=0,$B15,$B15+$A$5),E$3) -> 10 | F15: =INDEX(Datos!$C$4:$BT$732,IF(F$4=0,$B15,$B15+$A$5),F$3) -> 9460.9386 | G15: =INDEX(Datos!$C$4:$BT$732,IF(G$4=0,$B15,$B15+$A$5),G$3) -> 10 | H15: =INDEX(Datos!$C$4:$BT$732,IF(H$4=0,$B15,$B15+$A$5),H$3) -> 9460.9386 | I15: =INDEX(Datos!$C$4:$BT$732,IF(I$4=0,$B15,$B15+$A$5),I$3) -> 10 | J15: =INDEX(Datos!$C$4:$BT$732,IF(J$4=0,$B15,$B15+$A$5),J$3) -> 9460.9386 | ... EL15: =INDEX(Datos!$C$4:$BT$732,IF(EL$4=0,$B15,$B15+$A$5),EL$3) -> 8.188 | EM15: =INDEX(Datos!$C$4:$BY$732,IF(EM$4=0,$B15,$B15+$A$5),EM$3) -> 10 | EN15: =INDEX(Datos!$C$4:$BY$732,IF(EN$4=0,$B15,$B15+$A$5),EN$3) -> 8.188 | EO15: =INDEX(Datos!$C$4:$BY$732,IF(EO$4=0,$B15,$B15+$A$5),EO$3) -> 10 | EP15: =INDEX(Datos!$C$4:$BY$732,IF(EP$4=0,$B15,$B15+$A$5),EP$3) -> 8.188 | EQ15: =INDEX(Datos!$C$4:$BY$732,IF(EQ$4=0,$B15,$B15+$A$5),EQ$3) -> 10 | ER15: =INDEX(Datos!$C$4:$BY$732,IF(ER$4=0,$B15,$B15+$A$5),ER$3) -> 8.188 | ES15: =INDEX(Datos!$C$4:$BY$732,IF(ES$4=0,$B15,$B15+$A$5),ES$3) -> 10 | ET15: =INDEX(Datos!$C$4:$BY$732,IF(ET$4=0,$B15,$B15+$A$5),ET$3) -> 8.188 | ... EV15: =INDEX(Datos!$C$4:$BY$732,IF(EV$4=0,$B15,$B15+$A$5),EV$3) -> 8.188
B16: =B15+1 -> 12 | C16: =INDEX(Datos!$C$4:$BT$732,IF(C$4=0,$B16,$B16+$A$5),C$3) -> 11 | D16: =INDEX(Datos!$C$4:$BT$732,IF(D$4=0,$B16,$B16+$A$5),D$3) -> 9239.0186 | E16: =INDEX(Datos!$C$4:$BT$732,IF(E$4=0,$B16,$B16+$A$5),E$3) -> 11 | F16: =INDEX(Datos!$C$4:$BT$732,IF(F$4=0,$B16,$B16+$A$5),F$3) -> 9239.0186 | G16: =INDEX(Datos!$C$4:$BT$732,IF(G$4=0,$B16,$B16+$A$5),G$3) -> 11 | H16: =INDEX(Datos!$C$4:$BT$732,IF(H$4=0,$B16,$B16+$A$5),H$3) -> 9239.0186 | I16: =INDEX(Datos!$C$4:$BT$732,IF(I$4=0,$B16,$B16+$A$5),I$3) -> 11 | J16: =INDEX(Datos!$C$4:$BT$732,IF(J$4=0,$B16,$B16+$A$5),J$3) -> 9239.0186 | ... EL16: =INDEX(Datos!$C$4:$BT$732,IF(EL$4=0,$B16,$B16+$A$5),EL$3) -> 9.2525 | EM16: =INDEX(Datos!$C$4:$BY$732,IF(EM$4=0,$B16,$B16+$A$5),EM$3) -> 11 | EN16: =INDEX(Datos!$C$4:$BY$732,IF(EN$4=0,$B16,$B16+$A$5),EN$3) -> 9.2525 | EO16: =INDEX(Datos!$C$4:$BY$732,IF(EO$4=0,$B16,$B16+$A$5),EO$3) -> 11 | EP16: =INDEX(Datos!$C$4:$BY$732,IF(EP$4=0,$B16,$B16+$A$5),EP$3) -> 9.2525 | EQ16: =INDEX(Datos!$C$4:$BY$732,IF(EQ$4=0,$B16,$B16+$A$5),EQ$3) -> 11 | ER16: =INDEX(Datos!$C$4:$BY$732,IF(ER$4=0,$B16,$B16+$A$5),ER$3) -> 9.2525 | ES16: =INDEX(Datos!$C$4:$BY$732,IF(ES$4=0,$B16,$B16+$A$5),ES$3) -> 11 | ET16: =INDEX(Datos!$C$4:$BY$732,IF(ET$4=0,$B16,$B16+$A$5),ET$3) -> 9.2525 | ... EV16: =INDEX(Datos!$C$4:$BY$732,IF(EV$4=0,$B16,$B16+$A$5),EV$3) -> 9.2525
B17: =B16+1 -> 13 | C17: =INDEX(Datos!$C$4:$BT$732,IF(C$4=0,$B17,$B17+$A$5),C$3) -> 12 | D17: =INDEX(Datos!$C$4:$BT$732,IF(D$4=0,$B17,$B17+$A$5),D$3) -> 5616.5134 | E17: =INDEX(Datos!$C$4:$BT$732,IF(E$4=0,$B17,$B17+$A$5),E$3) -> 12 | F17: =INDEX(Datos!$C$4:$BT$732,IF(F$4=0,$B17,$B17+$A$5),F$3) -> 5616.5134 | G17: =INDEX(Datos!$C$4:$BT$732,IF(G$4=0,$B17,$B17+$A$5),G$3) -> 12 | H17: =INDEX(Datos!$C$4:$BT$732,IF(H$4=0,$B17,$B17+$A$5),H$3) -> 5616.5134 | I17: =INDEX(Datos!$C$4:$BT$732,IF(I$4=0,$B17,$B17+$A$5),I$3) -> 12 | J17: =INDEX(Datos!$C$4:$BT$732,IF(J$4=0,$B17,$B17+$A$5),J$3) -> 5616.5134 | ... EL17: =INDEX(Datos!$C$4:$BT$732,IF(EL$4=0,$B17,$B17+$A$5),EL$3) -> 10.7655 | EM17: =INDEX(Datos!$C$4:$BY$732,IF(EM$4=0,$B17,$B17+$A$5),EM$3) -> 12 | EN17: =INDEX(Datos!$C$4:$BY$732,IF(EN$4=0,$B17,$B17+$A$5),EN$3) -> 10.7655 | EO17: =INDEX(Datos!$C$4:$BY$732,IF(EO$4=0,$B17,$B17+$A$5),EO$3) -> 12 | EP17: =INDEX(Datos!$C$4:$BY$732,IF(EP$4=0,$B17,$B17+$A$5),EP$3) -> 10.7655 | EQ17: =INDEX(Datos!$C$4:$BY$732,IF(EQ$4=0,$B17,$B17+$A$5),EQ$3) -> 12 | ER17: =INDEX(Datos!$C$4:$BY$732,IF(ER$4=0,$B17,$B17+$A$5),ER$3) -> 10.7655 | ES17: =INDEX(Datos!$C$4:$BY$732,IF(ES$4=0,$B17,$B17+$A$5),ES$3) -> 12 | ET17: =INDEX(Datos!$C$4:$BY$732,IF(ET$4=0,$B17,$B17+$A$5),ET$3) -> 10.7655 | ... EV17: =INDEX(Datos!$C$4:$BY$732,IF(EV$4=0,$B17,$B17+$A$5),EV$3) -> 10.7655
B18: =B17+1 -> 14 | C18: =INDEX(Datos!$C$4:$BT$732,IF(C$4=0,$B18,$B18+$A$5),C$3) -> 13 | D18: =INDEX(Datos!$C$4:$BT$732,IF(D$4=0,$B18,$B18+$A$5),D$3) -> 4140.0976 | E18: =INDEX(Datos!$C$4:$BT$732,IF(E$4=0,$B18,$B18+$A$5),E$3) -> 13 | F18: =INDEX(Datos!$C$4:$BT$732,IF(F$4=0,$B18,$B18+$A$5),F$3) -> 4140.0976 | G18: =INDEX(Datos!$C$4:$BT$732,IF(G$4=0,$B18,$B18+$A$5),G$3) -> 13 | H18: =INDEX(Datos!$C$4:$BT$732,IF(H$4=0,$B18,$B18+$A$5),H$3) -> 4140.0976 | I18: =INDEX(Datos!$C$4:$BT$732,IF(I$4=0,$B18,$B18+$A$5),I$3) -> 13 | J18: =INDEX(Datos!$C$4:$BT$732,IF(J$4=0,$B18,$B18+$A$5),J$3) -> 4140.0976 | ... EL18: =INDEX(Datos!$C$4:$BT$732,IF(EL$4=0,$B18,$B18+$A$5),EL$3) -> 11.1005 | EM18: =INDEX(Datos!$C$4:$BY$732,IF(EM$4=0,$B18,$B18+$A$5),EM$3) -> 13 | EN18: =INDEX(Datos!$C$4:$BY$732,IF(EN$4=0,$B18,$B18+$A$5),EN$3) -> 11.1005 | EO18: =INDEX(Datos!$C$4:$BY$732,IF(EO$4=0,$B18,$B18+$A$5),EO$3) -> 13 | EP18: =INDEX(Datos!$C$4:$BY$732,IF(EP$4=0,$B18,$B18+$A$5),EP$3) -> 11.1005 | EQ18: =INDEX(Datos!$C$4:$BY$732,IF(EQ$4=0,$B18,$B18+$A$5),EQ$3) -> 13 | ER18: =INDEX(Datos!$C$4:$BY$732,IF(ER$4=0,$B18,$B18+$A$5),ER$3) -> 11.1005 | ES18: =INDEX(Datos!$C$4:$BY$732,IF(ES$4=0,$B18,$B18+$A$5),ES$3) -> 13 | ET18: =INDEX(Datos!$C$4:$BY$732,IF(ET$4=0,$B18,$B18+$A$5),ET$3) -> 11.1005 | ... EV18: =INDEX(Datos!$C$4:$BY$732,IF(EV$4=0,$B18,$B18+$A$5),EV$3) -> 11.1005
... B364: =B363+1 -> 360 | C364: =INDEX(Datos!$C$4:$BT$732,IF(C$4=0,$B364,$B364+$A$5),C$3) -> 359 | D364: =INDEX(Datos!$C$4:$BT$732,IF(D$4=0,$B364,$B364+$A$5),D$3) -> 6856.35 | E364: =INDEX(Datos!$C$4:$BT$732,IF(E$4=0,$B364,$B364+$A$5),E$3) -> 359 | F364: =INDEX(Datos!$C$4:$BT$732,IF(F$4=0,$B364,$B364+$A$5),F$3) -> 8726.5476 | G364: =INDEX(Datos!$C$4:$BT$732,IF(G$4=0,$B364,$B364+$A$5),G$3) -> 359 | H364: =INDEX(Datos!$C$4:$BT$732,IF(H$4=0,$B364,$B364+$A$5),H$3) -> 8883.4438 | I364: =INDEX(Datos!$C$4:$BT$732,IF(I$4=0,$B364,$B364+$A$5),I$3) -> 359 | J364: =INDEX(Datos!$C$4:$BT$732,IF(J$4=0,$B364,$B364+$A$5),J$3) -> 8972.8586 | ... EL364: =INDEX(Datos!$C$4:$BT$732,IF(EL$4=0,$B364,$B364+$A$5),EL$3) -> 9.93 | EM364: =INDEX(Datos!$C$4:$BY$732,IF(EM$4=0,$B364,$B364+$A$5),EM$3) -> 359 | EN364: =INDEX(Datos!$C$4:$BY$732,IF(EN$4=0,$B364,$B364+$A$5),EN$3) -> 8.631 | EO364: =INDEX(Datos!$C$4:$BY$732,IF(EO$4=0,$B364,$B364+$A$5),EO$3) -> 359 | EP364: =INDEX(Datos!$C$4:$BY$732,IF(EP$4=0,$B364,$B364+$A$5),EP$3) -> 8.631 | EQ364: =INDEX(Datos!$C$4:$BY$732,IF(EQ$4=0,$B364,$B364+$A$5),EQ$3) -> 359 | ER364: =INDEX(Datos!$C$4:$BY$732,IF(ER$4=0,$B364,$B364+$A$5),ER$3) -> 8.6944444 | ES364: =INDEX(Datos!$C$4:$BY$732,IF(ES$4=0,$B364,$B364+$A$5),ES$3) -> 359 | ET364: =INDEX(Datos!$C$4:$BY$732,IF(ET$4=0,$B364,$B364+$A$5),ET$3) -> 8.714 | ... EV364: =INDEX(Datos!$C$4:$BY$732,IF(EV$4=0,$B364,$B364+$A$5),EV$3) -> 8.631
